Repo Hash (Nightly Test):     [ddce21c]
Deploying Cloudformation stack...
Nightly Test in the (TODO FIXME) account
Stack Name: [unity-management-console-unity-nightly]
Stack Status (Final): [CREATE_COMPLETE]
Stack Creation Time: [440 seconds] - PASS
Deploying Management Console...
============================= test session starts ==============================
platform linux -- Python 3.8.10, pytest-8.3.2, pluggy-1.5.0 -- /usr/bin/python3
cachedir: .pytest_cache
rootdir: /home/ubuntu/unity-cs-infra/nightly_tests
collecting ... collected 4 items

test_selenium_mc.py::test_navigate_to_mc_console PASSED                  [ 25%]
test_selenium_mc.py::test_bootstrap_process_status PASSED                [ 50%]
test_selenium_mc.py::test_initiate_core_setup FAILED                     [ 75%]
test_selenium_mc.py::test_core_setup_save_btn FAILED                     [100%]

=================================== FAILURES ===================================
___________________________ test_initiate_core_setup ___________________________
test_selenium_mc.py:95: in test_initiate_core_setup
    go_button = WebDriverWait(driver, 20).until(
../../.local/lib/python3.8/site-packages/selenium/webdriver/support/wait.py:105: in until
    raise TimeoutException(message, screen, stacktrace)
E   selenium.common.exceptions.TimeoutException: Message: 
E   Stacktrace:
E   #0 0x55a4e172f6ca <unknown>
E   #1 0x55a4e1400600 <unknown>
E   #2 0x55a4e144fbcb <unknown>
E   #3 0x55a4e144feb1 <unknown>
E   #4 0x55a4e1493b24 <unknown>
E   #5 0x55a4e14728cd <unknown>
E   #6 0x55a4e149104a <unknown>
E   #7 0x55a4e1472643 <unknown>
E   #8 0x55a4e1442d31 <unknown>
E   #9 0x55a4e144379e <unknown>
E   #10 0x55a4e16f725b <unknown>
E   #11 0x55a4e16fb1f2 <unknown>
E   #12 0x55a4e16e4615 <unknown>
E   #13 0x55a4e16fbd82 <unknown>
E   #14 0x55a4e16c925f <unknown>
E   #15 0x55a4e171ee68 <unknown>
E   #16 0x55a4e171f040 <unknown>
E   #17 0x55a4e172e49c <unknown>
E   #18 0x7f4a3daa2a94 <unknown>
E   #19 0x7f4a3db2fa34 __clone

During handling of the above exception, another exception occurred:
test_selenium_mc.py:104: in test_initiate_core_setup
    raise Exception("Failed to navigate to setup page - either the Go button was not clickable or the URL did not change as expected.")
E   Exception: Failed to navigate to setup page - either the Go button was not clickable or the URL did not change as expected.
___________________________ test_core_setup_save_btn ___________________________
test_selenium_mc.py:116: in test_core_setup_save_btn
    save_button = WebDriverWait(driver, 10).until(
../../.local/lib/python3.8/site-packages/selenium/webdriver/support/wait.py:105: in until
    raise TimeoutException(message, screen, stacktrace)
E   selenium.common.exceptions.TimeoutException: Message: 
E   Stacktrace:
E   #0 0x55a4e172f6ca <unknown>
E   #1 0x55a4e1400600 <unknown>
E   #2 0x55a4e144fbcb <unknown>
E   #3 0x55a4e144feb1 <unknown>
E   #4 0x55a4e1493b24 <unknown>
E   #5 0x55a4e14728cd <unknown>
E   #6 0x55a4e149104a <unknown>
E   #7 0x55a4e1472643 <unknown>
E   #8 0x55a4e1442d31 <unknown>
E   #9 0x55a4e144379e <unknown>
E   #10 0x55a4e16f725b <unknown>
E   #11 0x55a4e16fb1f2 <unknown>
E   #12 0x55a4e16e4615 <unknown>
E   #13 0x55a4e16fbd82 <unknown>
E   #14 0x55a4e16c925f <unknown>
E   #15 0x55a4e171ee68 <unknown>
E   #16 0x55a4e171f040 <unknown>
E   #17 0x55a4e172e49c <unknown>
E   #18 0x7f4a3daa2a94 <unknown>
E   #19 0x7f4a3db2fa34 __clone

During handling of the above exception, another exception occurred:
test_selenium_mc.py:128: in test_core_setup_save_btn
    raise Exception("Failed to find or click the core 'Save' button within the specified time.")
E   Exception: Failed to find or click the core 'Save' button within the specified time.
=========================== short test summary info ============================
FAILED test_selenium_mc.py::test_initiate_core_setup - Exception: Failed to n...
FAILED test_selenium_mc.py::test_core_setup_save_btn - Exception: Failed to f...
========================= 2 failed, 2 passed in 49.09s =========================
