Repo Hash (Nightly Test):     [07577a6]
Deploying Cloudformation stack...
-----------------------------------------
Items that will auto-deploy on bootstrap:
Marketplace Item                | Version
--------------------------------+--------
unity-cs-monitoring-lambda      | 0.1
unity-apigateway                | 0.4
unity-proxy                     | 0.14
unity-ui                        | 0.8.0
Nightly Test in the (TODO FIXME) account
Stack Name: [unity-management-console-unity-nightly]
Stack Status (Final): [CREATE_COMPLETE]
Stack Creation Time: [380 seconds] - PASS
Deploying Management Console...
============================= test session starts ==============================
platform linux -- Python 3.8.10, pytest-8.3.2, pluggy-1.5.0 -- /usr/bin/python3
cachedir: .pytest_cache
rootdir: /home/ubuntu/unity-monorepo/tests/nightly_tests
collecting ... collected 4 items

test_selenium_mc.py::test_navigate_to_mc_console FAILED                  [ 25%]
test_selenium_mc.py::test_bootstrap_process_status FAILED                [ 50%]
test_selenium_mc.py::test_initiate_core_setup FAILED                     [ 75%]
test_selenium_mc.py::test_core_setup_save_btn FAILED                     [100%]

=================================== FAILURES ===================================
_________________________ test_navigate_to_mc_console __________________________
test_selenium_mc.py:56: in test_navigate_to_mc_console
    driver.get(URL_WITHOUT_CRED)
../../../.local/lib/python3.8/site-packages/selenium/webdriver/remote/webdriver.py:363: in get
    self.execute(Command.GET, {"url": url})
../../../.local/lib/python3.8/site-packages/selenium/webdriver/remote/webdriver.py:354: in execute
    self.error_handler.check_response(response)
../../../.local/lib/python3.8/site-packages/selenium/webdriver/remote/errorhandler.py:229: in check_response
    raise exception_class(message, screen, stacktrace)
E   selenium.common.exceptions.WebDriverException: Message: unknown error: net::ERR_NAME_NOT_RESOLVED
E     (Session info: chrome=131.0.6778.108)
E   Stacktrace:
E   #0 0x557156fc234a <unknown>
E   #1 0x557156ad86e0 <unknown>
E   #2 0x557156ad08f4 <unknown>
E   #3 0x557156ac0c99 <unknown>
E   #4 0x557156ac29a4 <unknown>
E   #5 0x557156ac0f4d <unknown>
E   #6 0x557156ac07af <unknown>
E   #7 0x557156ac06a2 <unknown>
E   #8 0x557156abe6c6 <unknown>
E   #9 0x557156abed3a <unknown>
E   #10 0x557156adb009 <unknown>
E   #11 0x557156b6ab35 <unknown>
E   #12 0x557156b4b462 <unknown>
E   #13 0x557156b69ed7 <unknown>
E   #14 0x557156b4b203 <unknown>
E   #15 0x557156b19cc0 <unknown>
E   #16 0x557156b1ac9e <unknown>
E   #17 0x557156f8fd3b <unknown>
E   #18 0x557156f93cc2 <unknown>
E   #19 0x557156f7cb6c <unknown>
E   #20 0x557156f94837 <unknown>
E   #21 0x557156f6210f <unknown>
E   #22 0x557156fb15a8 <unknown>
E   #23 0x557156fb1770 <unknown>
E   #24 0x557156fc11c6 <unknown>
E   #25 0x7fc8f353ca94 <unknown>
E   #26 0x7fc8f35c9a34 __clone
________________________ test_bootstrap_process_status _________________________
test_selenium_mc.py:77: in test_bootstrap_process_status
    bootstrap_status_element = WebDriverWait(driver, 10).until(
../../../.local/lib/python3.8/site-packages/selenium/webdriver/support/wait.py:105: in until
    raise TimeoutException(message, screen, stacktrace)
E   selenium.common.exceptions.TimeoutException: Message: 
E   Stacktrace:
E   #0 0x557156fc234a <unknown>
E   #1 0x557156ad86e0 <unknown>
E   #2 0x557156b273e6 <unknown>
E   #3 0x557156b27681 <unknown>
E   #4 0x557156b6cb04 <unknown>
E   #5 0x557156b4b48d <unknown>
E   #6 0x557156b69ed7 <unknown>
E   #7 0x557156b4b203 <unknown>
E   #8 0x557156b19cc0 <unknown>
E   #9 0x557156b1ac9e <unknown>
E   #10 0x557156f8fd3b <unknown>
E   #11 0x557156f93cc2 <unknown>
E   #12 0x557156f7cb6c <unknown>
E   #13 0x557156f94837 <unknown>
E   #14 0x557156f6210f <unknown>
E   #15 0x557156fb15a8 <unknown>
E   #16 0x557156fb1770 <unknown>
E   #17 0x557156fc11c6 <unknown>
E   #18 0x7fc8f353ca94 <unknown>
E   #19 0x7fc8f35c9a34 __clone

During handling of the above exception, another exception occurred:
test_selenium_mc.py:89: in test_bootstrap_process_status
    raise Exception("Failed to find the bootstrap status message within the specified time.")
E   Exception: Failed to find the bootstrap status message within the specified time.
___________________________ test_initiate_core_setup ___________________________
test_selenium_mc.py:95: in test_initiate_core_setup
    go_button = WebDriverWait(driver, 20).until(
../../../.local/lib/python3.8/site-packages/selenium/webdriver/support/wait.py:105: in until
    raise TimeoutException(message, screen, stacktrace)
E   selenium.common.exceptions.TimeoutException: Message: 
E   Stacktrace:
E   #0 0x557156fc234a <unknown>
E   #1 0x557156ad86e0 <unknown>
E   #2 0x557156b273e6 <unknown>
E   #3 0x557156b27681 <unknown>
E   #4 0x557156b6cb04 <unknown>
E   #5 0x557156b4b48d <unknown>
E   #6 0x557156b69ed7 <unknown>
E   #7 0x557156b4b203 <unknown>
E   #8 0x557156b19cc0 <unknown>
E   #9 0x557156b1ac9e <unknown>
E   #10 0x557156f8fd3b <unknown>
E   #11 0x557156f93cc2 <unknown>
E   #12 0x557156f7cb6c <unknown>
E   #13 0x557156f94837 <unknown>
E   #14 0x557156f6210f <unknown>
E   #15 0x557156fb15a8 <unknown>
E   #16 0x557156fb1770 <unknown>
E   #17 0x557156fc11c6 <unknown>
E   #18 0x7fc8f353ca94 <unknown>
E   #19 0x7fc8f35c9a34 __clone

During handling of the above exception, another exception occurred:
test_selenium_mc.py:104: in test_initiate_core_setup
    raise Exception("Failed to navigate to setup page - either the Go button was not clickable or the URL did not change as expected.")
E   Exception: Failed to navigate to setup page - either the Go button was not clickable or the URL did not change as expected.
___________________________ test_core_setup_save_btn ___________________________
test_selenium_mc.py:116: in test_core_setup_save_btn
    save_button = WebDriverWait(driver, 10).until(
../../../.local/lib/python3.8/site-packages/selenium/webdriver/support/wait.py:105: in until
    raise TimeoutException(message, screen, stacktrace)
E   selenium.common.exceptions.TimeoutException: Message: 
E   Stacktrace:
E   #0 0x557156fc234a <unknown>
E   #1 0x557156ad86e0 <unknown>
E   #2 0x557156b273e6 <unknown>
E   #3 0x557156b27681 <unknown>
E   #4 0x557156b6cb04 <unknown>
E   #5 0x557156b4b48d <unknown>
E   #6 0x557156b69ed7 <unknown>
E   #7 0x557156b4b203 <unknown>
E   #8 0x557156b19cc0 <unknown>
E   #9 0x557156b1ac9e <unknown>
E   #10 0x557156f8fd3b <unknown>
E   #11 0x557156f93cc2 <unknown>
E   #12 0x557156f7cb6c <unknown>
E   #13 0x557156f94837 <unknown>
E   #14 0x557156f6210f <unknown>
E   #15 0x557156fb15a8 <unknown>
E   #16 0x557156fb1770 <unknown>
E   #17 0x557156fc11c6 <unknown>
E   #18 0x7fc8f353ca94 <unknown>
E   #19 0x7fc8f35c9a34 __clone

During handling of the above exception, another exception occurred:
test_selenium_mc.py:128: in test_core_setup_save_btn
    raise Exception("Failed to find or click the core 'Save' button within the specified time.")
E   Exception: Failed to find or click the core 'Save' button within the specified time.
=========================== short test summary info ============================
FAILED test_selenium_mc.py::test_navigate_to_mc_console - selenium.common.exc...
FAILED test_selenium_mc.py::test_bootstrap_process_status - Exception: Failed...
FAILED test_selenium_mc.py::test_initiate_core_setup - Exception: Failed to n...
FAILED test_selenium_mc.py::test_core_setup_save_btn - Exception: Failed to f...
========================= 4 failed in 62.57s (0:01:02) =========================
