Repo Hash (Nightly Test):     [6e62e91]
Deploying Cloudformation stack...
Marketplace Items:
Marketplace Item                | Version
--------------------------------+--------
unity-cs-monitoring-lambda      | 0.1
unity-apigateway                | 0.4
unity-proxy                     | 0.14
unity-ui                        | 0.1
Nightly Test in the (TODO FIXME) account
Stack Name: [unity-management-console-unity-nightly]
Cloudformation Stack creation exceeded 2400 seconds - [FAIL]
Deploying Management Console...
============================= test session starts ==============================
platform linux -- Python 3.8.10, pytest-8.3.2, pluggy-1.5.0 -- /usr/bin/python3
cachedir: .pytest_cache
rootdir: /home/ubuntu/unity-cs-infra/nightly_tests
collecting ... collected 4 items

test_selenium_mc.py::test_navigate_to_mc_console FAILED                  [ 25%]
test_selenium_mc.py::test_bootstrap_process_status FAILED                [ 50%]
test_selenium_mc.py::test_initiate_core_setup FAILED                     [ 75%]
test_selenium_mc.py::test_core_setup_save_btn FAILED                     [100%]

=================================== FAILURES ===================================
_________________________ test_navigate_to_mc_console __________________________
test_selenium_mc.py:56: in test_navigate_to_mc_console
    driver.get(URL_WITHOUT_CRED)
../../.local/lib/python3.8/site-packages/selenium/webdriver/remote/webdriver.py:363: in get
    self.execute(Command.GET, {"url": url})
../../.local/lib/python3.8/site-packages/selenium/webdriver/remote/webdriver.py:354: in execute
    self.error_handler.check_response(response)
../../.local/lib/python3.8/site-packages/selenium/webdriver/remote/errorhandler.py:229: in check_response
    raise exception_class(message, screen, stacktrace)
E   selenium.common.exceptions.InvalidArgumentException: Message: invalid argument
E     (Session info: chrome=130.0.6723.91)
E   Stacktrace:
E   #0 0x560a6737213a <unknown>
E   #1 0x560a66e8d2bd <unknown>
E   #2 0x560a66e7516f <unknown>
E   #3 0x560a66e737c8 <unknown>
E   #4 0x560a66e73eba <unknown>
E   #5 0x560a66e8fd59 <unknown>
E   #6 0x560a66f1d645 <unknown>
E   #7 0x560a66efe012 <unknown>
E   #8 0x560a66f1caf6 <unknown>
E   #9 0x560a66efddb3 <unknown>
E   #10 0x560a66eccc10 <unknown>
E   #11 0x560a66ecdbee <unknown>
E   #12 0x560a6733e3cb <unknown>
E   #13 0x560a67342368 <unknown>
E   #14 0x560a6732beec <unknown>
E   #15 0x560a67342ee7 <unknown>
E   #16 0x560a6731113f <unknown>
E   #17 0x560a67360858 <unknown>
E   #18 0x560a67360a20 <unknown>
E   #19 0x560a67370fb6 <unknown>
E   #20 0x7fcf7c206a94 <unknown>
E   #21 0x7fcf7c293a34 __clone
________________________ test_bootstrap_process_status _________________________
test_selenium_mc.py:77: in test_bootstrap_process_status
    bootstrap_status_element = WebDriverWait(driver, 10).until(
../../.local/lib/python3.8/site-packages/selenium/webdriver/support/wait.py:105: in until
    raise TimeoutException(message, screen, stacktrace)
E   selenium.common.exceptions.TimeoutException: Message: 
E   Stacktrace:
E   #0 0x560a6737213a <unknown>
E   #1 0x560a66e8d460 <unknown>
E   #2 0x560a66ed9f96 <unknown>
E   #3 0x560a66eda221 <unknown>
E   #4 0x560a66f1f5d4 <unknown>
E   #5 0x560a66efe03d <unknown>
E   #6 0x560a66f1caf6 <unknown>
E   #7 0x560a66efddb3 <unknown>
E   #8 0x560a66eccc10 <unknown>
E   #9 0x560a66ecdbee <unknown>
E   #10 0x560a6733e3cb <unknown>
E   #11 0x560a67342368 <unknown>
E   #12 0x560a6732beec <unknown>
E   #13 0x560a67342ee7 <unknown>
E   #14 0x560a6731113f <unknown>
E   #15 0x560a67360858 <unknown>
E   #16 0x560a67360a20 <unknown>
E   #17 0x560a67370fb6 <unknown>
E   #18 0x7fcf7c206a94 <unknown>
E   #19 0x7fcf7c293a34 __clone

During handling of the above exception, another exception occurred:
test_selenium_mc.py:89: in test_bootstrap_process_status
    raise Exception("Failed to find the bootstrap status message within the specified time.")
E   Exception: Failed to find the bootstrap status message within the specified time.
___________________________ test_initiate_core_setup ___________________________
test_selenium_mc.py:95: in test_initiate_core_setup
    go_button = WebDriverWait(driver, 20).until(
../../.local/lib/python3.8/site-packages/selenium/webdriver/support/wait.py:105: in until
    raise TimeoutException(message, screen, stacktrace)
E   selenium.common.exceptions.TimeoutException: Message: 
E   Stacktrace:
E   #0 0x560a6737213a <unknown>
E   #1 0x560a66e8d460 <unknown>
E   #2 0x560a66ed9f96 <unknown>
E   #3 0x560a66eda221 <unknown>
E   #4 0x560a66f1f5d4 <unknown>
E   #5 0x560a66efe03d <unknown>
E   #6 0x560a66f1caf6 <unknown>
E   #7 0x560a66efddb3 <unknown>
E   #8 0x560a66eccc10 <unknown>
E   #9 0x560a66ecdbee <unknown>
E   #10 0x560a6733e3cb <unknown>
E   #11 0x560a67342368 <unknown>
E   #12 0x560a6732beec <unknown>
E   #13 0x560a67342ee7 <unknown>
E   #14 0x560a6731113f <unknown>
E   #15 0x560a67360858 <unknown>
E   #16 0x560a67360a20 <unknown>
E   #17 0x560a67370fb6 <unknown>
E   #18 0x7fcf7c206a94 <unknown>
E   #19 0x7fcf7c293a34 __clone

During handling of the above exception, another exception occurred:
test_selenium_mc.py:104: in test_initiate_core_setup
    raise Exception("Failed to navigate to setup page - either the Go button was not clickable or the URL did not change as expected.")
E   Exception: Failed to navigate to setup page - either the Go button was not clickable or the URL did not change as expected.
___________________________ test_core_setup_save_btn ___________________________
test_selenium_mc.py:116: in test_core_setup_save_btn
    save_button = WebDriverWait(driver, 10).until(
../../.local/lib/python3.8/site-packages/selenium/webdriver/support/wait.py:105: in until
    raise TimeoutException(message, screen, stacktrace)
E   selenium.common.exceptions.TimeoutException: Message: 
E   Stacktrace:
E   #0 0x560a6737213a <unknown>
E   #1 0x560a66e8d460 <unknown>
E   #2 0x560a66ed9f96 <unknown>
E   #3 0x560a66eda221 <unknown>
E   #4 0x560a66f1f5d4 <unknown>
E   #5 0x560a66efe03d <unknown>
E   #6 0x560a66f1caf6 <unknown>
E   #7 0x560a66efddb3 <unknown>
E   #8 0x560a66eccc10 <unknown>
E   #9 0x560a66ecdbee <unknown>
E   #10 0x560a6733e3cb <unknown>
E   #11 0x560a67342368 <unknown>
E   #12 0x560a6732beec <unknown>
E   #13 0x560a67342ee7 <unknown>
E   #14 0x560a6731113f <unknown>
E   #15 0x560a67360858 <unknown>
E   #16 0x560a67360a20 <unknown>
E   #17 0x560a67370fb6 <unknown>
E   #18 0x7fcf7c206a94 <unknown>
E   #19 0x7fcf7c293a34 __clone

During handling of the above exception, another exception occurred:
test_selenium_mc.py:128: in test_core_setup_save_btn
    raise Exception("Failed to find or click the core 'Save' button within the specified time.")
E   Exception: Failed to find or click the core 'Save' button within the specified time.
=========================== short test summary info ============================
FAILED test_selenium_mc.py::test_navigate_to_mc_console - selenium.common.exc...
FAILED test_selenium_mc.py::test_bootstrap_process_status - Exception: Failed...
FAILED test_selenium_mc.py::test_initiate_core_setup - Exception: Failed to n...
FAILED test_selenium_mc.py::test_core_setup_save_btn - Exception: Failed to f...
============================== 4 failed in 56.60s ==============================
