Repo Hash (Nightly Test):     [c97c760]
Deploying Cloudformation stack...
Nightly Test in the (TODO FIXME) account
Stack Name: [unity-management-console-unity-nightly]
Cloudformation Stack creation exceeded 2400 seconds - [FAIL]
Deploying Management Console...
============================= test session starts ==============================
platform linux -- Python 3.8.10, pytest-8.3.2, pluggy-1.5.0 -- /usr/bin/python3
cachedir: .pytest_cache
rootdir: /home/ubuntu/unity-cs-infra/nightly_tests
collecting ... collected 4 items

test_selenium_mc.py::test_navigate_to_mc_console FAILED                  [ 25%]
test_selenium_mc.py::test_bootstrap_process_status FAILED                [ 50%]
test_selenium_mc.py::test_initiate_core_setup FAILED                     [ 75%]
test_selenium_mc.py::test_core_setup_save_btn FAILED                     [100%]

=================================== FAILURES ===================================
_________________________ test_navigate_to_mc_console __________________________
test_selenium_mc.py:56: in test_navigate_to_mc_console
    driver.get(URL_WITHOUT_CRED)
../../.local/lib/python3.8/site-packages/selenium/webdriver/remote/webdriver.py:363: in get
    self.execute(Command.GET, {"url": url})
../../.local/lib/python3.8/site-packages/selenium/webdriver/remote/webdriver.py:354: in execute
    self.error_handler.check_response(response)
../../.local/lib/python3.8/site-packages/selenium/webdriver/remote/errorhandler.py:229: in check_response
    raise exception_class(message, screen, stacktrace)
E   selenium.common.exceptions.InvalidArgumentException: Message: invalid argument
E     (Session info: chrome=128.0.6613.119)
E   Stacktrace:
E   #0 0x55f1f95fd86a <unknown>
E   #1 0x55f1f92cbc91 <unknown>
E   #2 0x55f1f92b3343 <unknown>
E   #3 0x55f1f92b1a66 <unknown>
E   #4 0x55f1f92b21aa <unknown>
E   #5 0x55f1f92ce771 <unknown>
E   #6 0x55f1f935f515 <unknown>
E   #7 0x55f1f9340492 <unknown>
E   #8 0x55f1f935e9c6 <unknown>
E   #9 0x55f1f9340233 <unknown>
E   #10 0x55f1f930e093 <unknown>
E   #11 0x55f1f930f09e <unknown>
E   #12 0x55f1f95c4acb <unknown>
E   #13 0x55f1f95c8a81 <unknown>
E   #14 0x55f1f95b0695 <unknown>
E   #15 0x55f1f95c95f2 <unknown>
E   #16 0x55f1f959586f <unknown>
E   #17 0x55f1f95ec668 <unknown>
E   #18 0x55f1f95ec832 <unknown>
E   #19 0x55f1f95fc65c <unknown>
E   #20 0x7f626a637a94 <unknown>
E   #21 0x7f626a6c4a34 __clone
________________________ test_bootstrap_process_status _________________________
test_selenium_mc.py:77: in test_bootstrap_process_status
    bootstrap_status_element = WebDriverWait(driver, 10).until(
../../.local/lib/python3.8/site-packages/selenium/webdriver/support/wait.py:105: in until
    raise TimeoutException(message, screen, stacktrace)
E   selenium.common.exceptions.TimeoutException: Message: 
E   Stacktrace:
E   #0 0x55f1f95fd86a <unknown>
E   #1 0x55f1f92cbe50 <unknown>
E   #2 0x55f1f931b644 <unknown>
E   #3 0x55f1f931b931 <unknown>
E   #4 0x55f1f9361534 <unknown>
E   #5 0x55f1f93404bd <unknown>
E   #6 0x55f1f935e9c6 <unknown>
E   #7 0x55f1f9340233 <unknown>
E   #8 0x55f1f930e093 <unknown>
E   #9 0x55f1f930f09e <unknown>
E   #10 0x55f1f95c4acb <unknown>
E   #11 0x55f1f95c8a81 <unknown>
E   #12 0x55f1f95b0695 <unknown>
E   #13 0x55f1f95c95f2 <unknown>
E   #14 0x55f1f959586f <unknown>
E   #15 0x55f1f95ec668 <unknown>
E   #16 0x55f1f95ec832 <unknown>
E   #17 0x55f1f95fc65c <unknown>
E   #18 0x7f626a637a94 <unknown>
E   #19 0x7f626a6c4a34 __clone

During handling of the above exception, another exception occurred:
test_selenium_mc.py:89: in test_bootstrap_process_status
    raise Exception("Failed to find the bootstrap status message within the specified time.")
E   Exception: Failed to find the bootstrap status message within the specified time.
___________________________ test_initiate_core_setup ___________________________
test_selenium_mc.py:95: in test_initiate_core_setup
    go_button = WebDriverWait(driver, 20).until(
../../.local/lib/python3.8/site-packages/selenium/webdriver/support/wait.py:105: in until
    raise TimeoutException(message, screen, stacktrace)
E   selenium.common.exceptions.TimeoutException: Message: 
E   Stacktrace:
E   #0 0x55f1f95fd86a <unknown>
E   #1 0x55f1f92cbe50 <unknown>
E   #2 0x55f1f931b644 <unknown>
E   #3 0x55f1f931b931 <unknown>
E   #4 0x55f1f9361534 <unknown>
E   #5 0x55f1f93404bd <unknown>
E   #6 0x55f1f935e9c6 <unknown>
E   #7 0x55f1f9340233 <unknown>
E   #8 0x55f1f930e093 <unknown>
E   #9 0x55f1f930f09e <unknown>
E   #10 0x55f1f95c4acb <unknown>
E   #11 0x55f1f95c8a81 <unknown>
E   #12 0x55f1f95b0695 <unknown>
E   #13 0x55f1f95c95f2 <unknown>
E   #14 0x55f1f959586f <unknown>
E   #15 0x55f1f95ec668 <unknown>
E   #16 0x55f1f95ec832 <unknown>
E   #17 0x55f1f95fc65c <unknown>
E   #18 0x7f626a637a94 <unknown>
E   #19 0x7f626a6c4a34 __clone

During handling of the above exception, another exception occurred:
test_selenium_mc.py:104: in test_initiate_core_setup
    raise Exception("Failed to navigate to setup page - either the Go button was not clickable or the URL did not change as expected.")
E   Exception: Failed to navigate to setup page - either the Go button was not clickable or the URL did not change as expected.
___________________________ test_core_setup_save_btn ___________________________
test_selenium_mc.py:116: in test_core_setup_save_btn
    save_button = WebDriverWait(driver, 10).until(
../../.local/lib/python3.8/site-packages/selenium/webdriver/support/wait.py:105: in until
    raise TimeoutException(message, screen, stacktrace)
E   selenium.common.exceptions.TimeoutException: Message: 
E   Stacktrace:
E   #0 0x55f1f95fd86a <unknown>
E   #1 0x55f1f92cbe50 <unknown>
E   #2 0x55f1f931b644 <unknown>
E   #3 0x55f1f931b931 <unknown>
E   #4 0x55f1f9361534 <unknown>
E   #5 0x55f1f93404bd <unknown>
E   #6 0x55f1f935e9c6 <unknown>
E   #7 0x55f1f9340233 <unknown>
E   #8 0x55f1f930e093 <unknown>
E   #9 0x55f1f930f09e <unknown>
E   #10 0x55f1f95c4acb <unknown>
E   #11 0x55f1f95c8a81 <unknown>
E   #12 0x55f1f95b0695 <unknown>
E   #13 0x55f1f95c95f2 <unknown>
E   #14 0x55f1f959586f <unknown>
E   #15 0x55f1f95ec668 <unknown>
E   #16 0x55f1f95ec832 <unknown>
E   #17 0x55f1f95fc65c <unknown>
E   #18 0x7f626a637a94 <unknown>
E   #19 0x7f626a6c4a34 __clone

During handling of the above exception, another exception occurred:
test_selenium_mc.py:128: in test_core_setup_save_btn
    raise Exception("Failed to find or click the core 'Save' button within the specified time.")
E   Exception: Failed to find or click the core 'Save' button within the specified time.
=========================== short test summary info ============================
FAILED test_selenium_mc.py::test_navigate_to_mc_console - selenium.common.exc...
FAILED test_selenium_mc.py::test_bootstrap_process_status - Exception: Failed...
FAILED test_selenium_mc.py::test_initiate_core_setup - Exception: Failed to n...
FAILED test_selenium_mc.py::test_core_setup_save_btn - Exception: Failed to f...
============================== 4 failed in 55.42s ==============================
