Repo Hash (Nightly Test):     [4ed1b1b]
Repo Hash (Cloudformation):   [d7ba267]
Nightly Test in the unity-cm account
Stack Name: [unity-cs-nightly-management-console]
Stack Status (Final): [CREATE_COMPLETE]
Stack Creation Time: [20 seconds] - PASS
============================= test session starts ==============================
platform linux -- Python 3.8.10, pytest-7.4.3, pluggy-1.3.0 -- /usr/bin/python3
cachedir: .pytest_cache
rootdir: /home/ubuntu/unity-cs-infra/nightly_tests/nightly_tests_ondemand
collecting ... collected 17 items

test_selenium_mc.py::test_navigate_to_url_with_cred PASSED               [  5%]
test_selenium_mc.py::test_login_to_mc_console FAILED                     [ 11%]
test_selenium_mc.py::test_initiate_core_setup FAILED                     [ 17%]
test_selenium_mc.py::test_input_venue_name FAILED                        [ 23%]
test_selenium_mc.py::test_input_project_name FAILED                      [ 29%]
test_selenium_mc.py::test_core_setup_save_btn FAILED                     [ 35%]
test_selenium_mc.py::test_return_to_marketplace FAILED                   [ 41%]
test_selenium_mc.py::test_grab_terminal_output FAILED                    [ 47%]
test_selenium_mc.py::test_install_eks FAILED                             [ 52%]
test_selenium_mc.py::test_eks_module_name FAILED                         [ 58%]
test_selenium_mc.py::test_eks_module_branch FAILED                       [ 64%]
test_selenium_mc.py::test_click_first_button FAILED                      [ 70%]
test_selenium_mc.py::test_click_second_button FAILED                     [ 76%]
test_selenium_mc.py::test_click_third_button FAILED                      [ 82%]
test_selenium_mc.py::test_click_fourth_button FAILED                     [ 88%]
test_selenium_mc.py::test_click_fith_button FAILED                       [ 94%]
test_selenium_mc.py::test_grab_terminal_output_two FAILED                [100%]

=================================== FAILURES ===================================
___________________________ test_login_to_mc_console ___________________________
test_selenium_mc.py:72: in test_login_to_mc_console
    assert driver.title == 'Unity Management Console', "The page title should be Unity Management Console"
E   AssertionError: The page title should be Unity Management Console
E   assert '' == 'Unity Management Console'
E     - Unity Management Console
___________________________ test_initiate_core_setup ___________________________
test_selenium_mc.py:78: in test_initiate_core_setup
    go_button = WebDriverWait(driver, 20).until(
../../../.local/lib/python3.8/site-packages/selenium/webdriver/support/wait.py:101: in until
    raise TimeoutException(message, screen, stacktrace)
E   selenium.common.exceptions.TimeoutException: Message: 
E   Stacktrace:
E   #0 0x5597f5128f83 <unknown>
E   #1 0x5597f4de1cf7 <unknown>
E   #2 0x5597f4e3199e <unknown>
E   #3 0x5597f4e31aa1 <unknown>
E   #4 0x5597f4e7cd64 <unknown>
E   #5 0x5597f4e5b0dd <unknown>
E   #6 0x5597f4e7a006 <unknown>
E   #7 0x5597f4e5ae53 <unknown>
E   #8 0x5597f4e22dd4 <unknown>
E   #9 0x5597f4e241de <unknown>
E   #10 0x5597f50ed531 <unknown>
E   #11 0x5597f50f1455 <unknown>
E   #12 0x5597f50d9f55 <unknown>
E   #13 0x5597f50f20ef <unknown>
E   #14 0x5597f50bd99f <unknown>
E   #15 0x5597f5116008 <unknown>
E   #16 0x5597f51161d7 <unknown>
E   #17 0x5597f5128124 <unknown>
E   #18 0x7f6f2627eac3 <unknown>

During handling of the above exception, another exception occurred:
test_selenium_mc.py:87: in test_initiate_core_setup
    raise Exception("Failed to navigate to setup page - either the Go button was not clickable or the URL did not change as expected.")
E   Exception: Failed to navigate to setup page - either the Go button was not clickable or the URL did not change as expected.
____________________________ test_input_venue_name _____________________________
test_selenium_mc.py:102: in test_input_venue_name
    text_box = WebDriverWait(driver, 10).until(
../../../.local/lib/python3.8/site-packages/selenium/webdriver/support/wait.py:101: in until
    raise TimeoutException(message, screen, stacktrace)
E   selenium.common.exceptions.TimeoutException: Message: 
E   Stacktrace:
E   #0 0x5597f5128f83 <unknown>
E   #1 0x5597f4de1cf7 <unknown>
E   #2 0x5597f4e3199e <unknown>
E   #3 0x5597f4e31aa1 <unknown>
E   #4 0x5597f4e7cd64 <unknown>
E   #5 0x5597f4e5b0dd <unknown>
E   #6 0x5597f4e7a006 <unknown>
E   #7 0x5597f4e5ae53 <unknown>
E   #8 0x5597f4e22dd4 <unknown>
E   #9 0x5597f4e241de <unknown>
E   #10 0x5597f50ed531 <unknown>
E   #11 0x5597f50f1455 <unknown>
E   #12 0x5597f50d9f55 <unknown>
E   #13 0x5597f50f20ef <unknown>
E   #14 0x5597f50bd99f <unknown>
E   #15 0x5597f5116008 <unknown>
E   #16 0x5597f51161d7 <unknown>
E   #17 0x5597f5128124 <unknown>
E   #18 0x7f6f2627eac3 <unknown>

During handling of the above exception, another exception occurred:
test_selenium_mc.py:109: in test_input_venue_name
    raise Exception(f"Failed to find or interact with the text box for venue name (ID: {element_id}).")
E   Exception: Failed to find or interact with the text box for venue name (ID: venue).
___________________________ test_input_project_name ____________________________
test_selenium_mc.py:124: in test_input_project_name
    text_box = WebDriverWait(driver, 10).until(
../../../.local/lib/python3.8/site-packages/selenium/webdriver/support/wait.py:101: in until
    raise TimeoutException(message, screen, stacktrace)
E   selenium.common.exceptions.TimeoutException: Message: 
E   Stacktrace:
E   #0 0x5597f5128f83 <unknown>
E   #1 0x5597f4de1cf7 <unknown>
E   #2 0x5597f4e3199e <unknown>
E   #3 0x5597f4e31aa1 <unknown>
E   #4 0x5597f4e7cd64 <unknown>
E   #5 0x5597f4e5b0dd <unknown>
E   #6 0x5597f4e7a006 <unknown>
E   #7 0x5597f4e5ae53 <unknown>
E   #8 0x5597f4e22dd4 <unknown>
E   #9 0x5597f4e241de <unknown>
E   #10 0x5597f50ed531 <unknown>
E   #11 0x5597f50f1455 <unknown>
E   #12 0x5597f50d9f55 <unknown>
E   #13 0x5597f50f20ef <unknown>
E   #14 0x5597f50bd99f <unknown>
E   #15 0x5597f5116008 <unknown>
E   #16 0x5597f51161d7 <unknown>
E   #17 0x5597f5128124 <unknown>
E   #18 0x7f6f2627eac3 <unknown>

During handling of the above exception, another exception occurred:
test_selenium_mc.py:131: in test_input_project_name
    raise Exception(f"Failed to find or interact with the text box for project name (ID: {element_id}).")
E   Exception: Failed to find or interact with the text box for project name (ID: project).
___________________________ test_core_setup_save_btn ___________________________
test_selenium_mc.py:144: in test_core_setup_save_btn
    save_button = WebDriverWait(driver, 10).until(
../../../.local/lib/python3.8/site-packages/selenium/webdriver/support/wait.py:101: in until
    raise TimeoutException(message, screen, stacktrace)
E   selenium.common.exceptions.TimeoutException: Message: 
E   Stacktrace:
E   #0 0x5597f5128f83 <unknown>
E   #1 0x5597f4de1cf7 <unknown>
E   #2 0x5597f4e3199e <unknown>
E   #3 0x5597f4e31aa1 <unknown>
E   #4 0x5597f4e7cd64 <unknown>
E   #5 0x5597f4e5b0dd <unknown>
E   #6 0x5597f4e7a006 <unknown>
E   #7 0x5597f4e5ae53 <unknown>
E   #8 0x5597f4e22dd4 <unknown>
E   #9 0x5597f4e241de <unknown>
E   #10 0x5597f50ed531 <unknown>
E   #11 0x5597f50f1455 <unknown>
E   #12 0x5597f50d9f55 <unknown>
E   #13 0x5597f50f20ef <unknown>
E   #14 0x5597f50bd99f <unknown>
E   #15 0x5597f5116008 <unknown>
E   #16 0x5597f51161d7 <unknown>
E   #17 0x5597f5128124 <unknown>
E   #18 0x7f6f2627eac3 <unknown>

During handling of the above exception, another exception occurred:
test_selenium_mc.py:150: in test_core_setup_save_btn
    raise Exception("Failed to find or click the core'Save' button within the specified time.")
E   Exception: Failed to find or click the core'Save' button within the specified time.
__________________________ test_return_to_marketplace __________________________
test_selenium_mc.py:171: in test_return_to_marketplace
    go_button = WebDriverWait(driver, 20).until(
../../../.local/lib/python3.8/site-packages/selenium/webdriver/support/wait.py:101: in until
    raise TimeoutException(message, screen, stacktrace)
E   selenium.common.exceptions.TimeoutException: Message: 
E   Stacktrace:
E   #0 0x5597f5128f83 <unknown>
E   #1 0x5597f4de1cf7 <unknown>
E   #2 0x5597f4e3199e <unknown>
E   #3 0x5597f4e31aa1 <unknown>
E   #4 0x5597f4e7cd64 <unknown>
E   #5 0x5597f4e5b0dd <unknown>
E   #6 0x5597f4e7a006 <unknown>
E   #7 0x5597f4e5ae53 <unknown>
E   #8 0x5597f4e22dd4 <unknown>
E   #9 0x5597f4e241de <unknown>
E   #10 0x5597f50ed531 <unknown>
E   #11 0x5597f50f1455 <unknown>
E   #12 0x5597f50d9f55 <unknown>
E   #13 0x5597f50f20ef <unknown>
E   #14 0x5597f50bd99f <unknown>
E   #15 0x5597f5116008 <unknown>
E   #16 0x5597f51161d7 <unknown>
E   #17 0x5597f5128124 <unknown>
E   #18 0x7f6f2627eac3 <unknown>

During handling of the above exception, another exception occurred:
test_selenium_mc.py:180: in test_return_to_marketplace
    raise Exception("Failed to navigate to the marketplace - either the button was not clickable or the URL did not change as expected.")
E   Exception: Failed to navigate to the marketplace - either the button was not clickable or the URL did not change as expected.
__________________________ test_grab_terminal_output ___________________________
test_selenium_mc.py:193: in test_grab_terminal_output
    terminal_output_element = WebDriverWait(driver, 10).until(
../../../.local/lib/python3.8/site-packages/selenium/webdriver/support/wait.py:101: in until
    raise TimeoutException(message, screen, stacktrace)
E   selenium.common.exceptions.TimeoutException: Message: 
E   Stacktrace:
E   #0 0x5597f5128f83 <unknown>
E   #1 0x5597f4de1cf7 <unknown>
E   #2 0x5597f4e3199e <unknown>
E   #3 0x5597f4e31aa1 <unknown>
E   #4 0x5597f4e7cd64 <unknown>
E   #5 0x5597f4e5b0dd <unknown>
E   #6 0x5597f4e7a006 <unknown>
E   #7 0x5597f4e5ae53 <unknown>
E   #8 0x5597f4e22dd4 <unknown>
E   #9 0x5597f4e241de <unknown>
E   #10 0x5597f50ed531 <unknown>
E   #11 0x5597f50f1455 <unknown>
E   #12 0x5597f50d9f55 <unknown>
E   #13 0x5597f50f20ef <unknown>
E   #14 0x5597f50bd99f <unknown>
E   #15 0x5597f5116008 <unknown>
E   #16 0x5597f51161d7 <unknown>
E   #17 0x5597f5128124 <unknown>
E   #18 0x7f6f2627eac3 <unknown>

During handling of the above exception, another exception occurred:
test_selenium_mc.py:198: in test_grab_terminal_output
    raise Exception("Failed to find or load the terminal output element within the specified time.")
E   Exception: Failed to find or load the terminal output element within the specified time.
_______________________________ test_install_eks _______________________________
test_selenium_mc.py:213: in test_install_eks
    install_button = WebDriverWait(driver, 10).until(
../../../.local/lib/python3.8/site-packages/selenium/webdriver/support/wait.py:101: in until
    raise TimeoutException(message, screen, stacktrace)
E   selenium.common.exceptions.TimeoutException: Message: 
E   Stacktrace:
E   #0 0x5597f5128f83 <unknown>
E   #1 0x5597f4de1cf7 <unknown>
E   #2 0x5597f4e3199e <unknown>
E   #3 0x5597f4e31aa1 <unknown>
E   #4 0x5597f4e7cd64 <unknown>
E   #5 0x5597f4e5b0dd <unknown>
E   #6 0x5597f4e7a006 <unknown>
E   #7 0x5597f4e5ae53 <unknown>
E   #8 0x5597f4e22dd4 <unknown>
E   #9 0x5597f4e241de <unknown>
E   #10 0x5597f50ed531 <unknown>
E   #11 0x5597f50f1455 <unknown>
E   #12 0x5597f50d9f55 <unknown>
E   #13 0x5597f50f20ef <unknown>
E   #14 0x5597f50bd99f <unknown>
E   #15 0x5597f5116008 <unknown>
E   #16 0x5597f51161d7 <unknown>
E   #17 0x5597f5128124 <unknown>
E   #18 0x7f6f2627eac3 <unknown>

During handling of the above exception, another exception occurred:
test_selenium_mc.py:222: in test_install_eks
    raise Exception("Failed to install EKS - either the button was not clickable or the URL did not update as expected.")
E   Exception: Failed to install EKS - either the button was not clickable or the URL did not update as expected.
_____________________________ test_eks_module_name _____________________________
test_selenium_mc.py:234: in test_eks_module_name
    text_box = WebDriverWait(driver, 10).until(
../../../.local/lib/python3.8/site-packages/selenium/webdriver/support/wait.py:101: in until
    raise TimeoutException(message, screen, stacktrace)
E   selenium.common.exceptions.TimeoutException: Message: 
E   Stacktrace:
E   #0 0x5597f5128f83 <unknown>
E   #1 0x5597f4de1cf7 <unknown>
E   #2 0x5597f4e3199e <unknown>
E   #3 0x5597f4e31aa1 <unknown>
E   #4 0x5597f4e7cd64 <unknown>
E   #5 0x5597f4e5b0dd <unknown>
E   #6 0x5597f4e7a006 <unknown>
E   #7 0x5597f4e5ae53 <unknown>
E   #8 0x5597f4e22dd4 <unknown>
E   #9 0x5597f4e241de <unknown>
E   #10 0x5597f50ed531 <unknown>
E   #11 0x5597f50f1455 <unknown>
E   #12 0x5597f50d9f55 <unknown>
E   #13 0x5597f50f20ef <unknown>
E   #14 0x5597f50bd99f <unknown>
E   #15 0x5597f5116008 <unknown>
E   #16 0x5597f51161d7 <unknown>
E   #17 0x5597f5128124 <unknown>
E   #18 0x7f6f2627eac3 <unknown>

During handling of the above exception, another exception occurred:
test_selenium_mc.py:238: in test_eks_module_name
    raise Exception(f"Textbox for module name (ID: {element_id}) not found.")
E   Exception: Textbox for module name (ID: module) not found.
____________________________ test_eks_module_branch ____________________________
test_selenium_mc.py:252: in test_eks_module_branch
    text_box = WebDriverWait(driver, 10).until(
../../../.local/lib/python3.8/site-packages/selenium/webdriver/support/wait.py:101: in until
    raise TimeoutException(message, screen, stacktrace)
E   selenium.common.exceptions.TimeoutException: Message: 
E   Stacktrace:
E   #0 0x5597f5128f83 <unknown>
E   #1 0x5597f4de1cf7 <unknown>
E   #2 0x5597f4e3199e <unknown>
E   #3 0x5597f4e31aa1 <unknown>
E   #4 0x5597f4e7cd64 <unknown>
E   #5 0x5597f4e5b0dd <unknown>
E   #6 0x5597f4e7a006 <unknown>
E   #7 0x5597f4e5ae53 <unknown>
E   #8 0x5597f4e22dd4 <unknown>
E   #9 0x5597f4e241de <unknown>
E   #10 0x5597f50ed531 <unknown>
E   #11 0x5597f50f1455 <unknown>
E   #12 0x5597f50d9f55 <unknown>
E   #13 0x5597f50f20ef <unknown>
E   #14 0x5597f50bd99f <unknown>
E   #15 0x5597f5116008 <unknown>
E   #16 0x5597f51161d7 <unknown>
E   #17 0x5597f5128124 <unknown>
E   #18 0x7f6f2627eac3 <unknown>

During handling of the above exception, another exception occurred:
test_selenium_mc.py:256: in test_eks_module_branch
    raise Exception(f"Textbox for branch name (ID: {element_id}) not found.")
E   Exception: Textbox for branch name (ID: branch) not found.
___________________________ test_click_first_button ____________________________
test_selenium_mc.py:269: in test_click_first_button
    button = WebDriverWait(driver, 10).until(
../../../.local/lib/python3.8/site-packages/selenium/webdriver/support/wait.py:101: in until
    raise TimeoutException(message, screen, stacktrace)
E   selenium.common.exceptions.TimeoutException: Message: 
E   Stacktrace:
E   #0 0x5597f5128f83 <unknown>
E   #1 0x5597f4de1cf7 <unknown>
E   #2 0x5597f4e3199e <unknown>
E   #3 0x5597f4e31aa1 <unknown>
E   #4 0x5597f4e7cd64 <unknown>
E   #5 0x5597f4e5b0dd <unknown>
E   #6 0x5597f4e7a006 <unknown>
E   #7 0x5597f4e5ae53 <unknown>
E   #8 0x5597f4e22dd4 <unknown>
E   #9 0x5597f4e241de <unknown>
E   #10 0x5597f50ed531 <unknown>
E   #11 0x5597f50f1455 <unknown>
E   #12 0x5597f50d9f55 <unknown>
E   #13 0x5597f50f20ef <unknown>
E   #14 0x5597f50bd99f <unknown>
E   #15 0x5597f5116008 <unknown>
E   #16 0x5597f51161d7 <unknown>
E   #17 0x5597f5128124 <unknown>
E   #18 0x7f6f2627eac3 <unknown>

During handling of the above exception, another exception occurred:
test_selenium_mc.py:274: in test_click_first_button
    raise Exception(f"Failed to find or click the first button (class: {button_class}).")
E   Exception: Failed to find or click the first button (class: default-btn.next-step.svelte-1pvzwgg).
___________________________ test_click_second_button ___________________________
test_selenium_mc.py:285: in test_click_second_button
    button = WebDriverWait(driver, 10).until(
../../../.local/lib/python3.8/site-packages/selenium/webdriver/support/wait.py:101: in until
    raise TimeoutException(message, screen, stacktrace)
E   selenium.common.exceptions.TimeoutException: Message: 
E   Stacktrace:
E   #0 0x5597f5128f83 <unknown>
E   #1 0x5597f4de1cf7 <unknown>
E   #2 0x5597f4e3199e <unknown>
E   #3 0x5597f4e31aa1 <unknown>
E   #4 0x5597f4e7cd64 <unknown>
E   #5 0x5597f4e5b0dd <unknown>
E   #6 0x5597f4e7a006 <unknown>
E   #7 0x5597f4e5ae53 <unknown>
E   #8 0x5597f4e22dd4 <unknown>
E   #9 0x5597f4e241de <unknown>
E   #10 0x5597f50ed531 <unknown>
E   #11 0x5597f50f1455 <unknown>
E   #12 0x5597f50d9f55 <unknown>
E   #13 0x5597f50f20ef <unknown>
E   #14 0x5597f50bd99f <unknown>
E   #15 0x5597f5116008 <unknown>
E   #16 0x5597f51161d7 <unknown>
E   #17 0x5597f5128124 <unknown>
E   #18 0x7f6f2627eac3 <unknown>

During handling of the above exception, another exception occurred:
test_selenium_mc.py:290: in test_click_second_button
    raise Exception(f"Failed to find or click the second button (class: {button_class}).")
E   Exception: Failed to find or click the second button (class: default-btn.next-step.svelte-1pvzwgg).
___________________________ test_click_third_button ____________________________
test_selenium_mc.py:301: in test_click_third_button
    button = WebDriverWait(driver, 10).until(
../../../.local/lib/python3.8/site-packages/selenium/webdriver/support/wait.py:101: in until
    raise TimeoutException(message, screen, stacktrace)
E   selenium.common.exceptions.TimeoutException: Message: 
E   Stacktrace:
E   #0 0x5597f5128f83 <unknown>
E   #1 0x5597f4de1cf7 <unknown>
E   #2 0x5597f4e3199e <unknown>
E   #3 0x5597f4e31aa1 <unknown>
E   #4 0x5597f4e7cd64 <unknown>
E   #5 0x5597f4e5b0dd <unknown>
E   #6 0x5597f4e7a006 <unknown>
E   #7 0x5597f4e5ae53 <unknown>
E   #8 0x5597f4e22dd4 <unknown>
E   #9 0x5597f4e241de <unknown>
E   #10 0x5597f50ed531 <unknown>
E   #11 0x5597f50f1455 <unknown>
E   #12 0x5597f50d9f55 <unknown>
E   #13 0x5597f50f20ef <unknown>
E   #14 0x5597f50bd99f <unknown>
E   #15 0x5597f5116008 <unknown>
E   #16 0x5597f51161d7 <unknown>
E   #17 0x5597f5128124 <unknown>
E   #18 0x7f6f2627eac3 <unknown>

During handling of the above exception, another exception occurred:
test_selenium_mc.py:306: in test_click_third_button
    raise Exception(f"Failed to find or click the third button (class: {button_class}).")
E   Exception: Failed to find or click the third button (class: default-btn.next-step.svelte-1pvzwgg).
___________________________ test_click_fourth_button ___________________________
test_selenium_mc.py:350: in test_click_fourth_button
    button = WebDriverWait(driver, 10).until(
../../../.local/lib/python3.8/site-packages/selenium/webdriver/support/wait.py:101: in until
    raise TimeoutException(message, screen, stacktrace)
E   selenium.common.exceptions.TimeoutException: Message: 
E   Stacktrace:
E   #0 0x5597f5128f83 <unknown>
E   #1 0x5597f4de1cf7 <unknown>
E   #2 0x5597f4e3199e <unknown>
E   #3 0x5597f4e31aa1 <unknown>
E   #4 0x5597f4e7cd64 <unknown>
E   #5 0x5597f4e5b0dd <unknown>
E   #6 0x5597f4e7a006 <unknown>
E   #7 0x5597f4e5ae53 <unknown>
E   #8 0x5597f4e22dd4 <unknown>
E   #9 0x5597f4e241de <unknown>
E   #10 0x5597f50ed531 <unknown>
E   #11 0x5597f50f1455 <unknown>
E   #12 0x5597f50d9f55 <unknown>
E   #13 0x5597f50f20ef <unknown>
E   #14 0x5597f50bd99f <unknown>
E   #15 0x5597f5116008 <unknown>
E   #16 0x5597f51161d7 <unknown>
E   #17 0x5597f5128124 <unknown>
E   #18 0x7f6f2627eac3 <unknown>

During handling of the above exception, another exception occurred:
test_selenium_mc.py:355: in test_click_fourth_button
    raise Exception(f"Failed to find or click the fourth button (class: {button_class}).")
E   Exception: Failed to find or click the fourth button (class: btn.btn-primary.svelte-1pvzwgg).
____________________________ test_click_fith_button ____________________________
test_selenium_mc.py:333: in test_click_fith_button
    button = WebDriverWait(driver, 10).until(
../../../.local/lib/python3.8/site-packages/selenium/webdriver/support/wait.py:101: in until
    raise TimeoutException(message, screen, stacktrace)
E   selenium.common.exceptions.TimeoutException: Message: 
E   Stacktrace:
E   #0 0x5597f5128f83 <unknown>
E   #1 0x5597f4de1cf7 <unknown>
E   #2 0x5597f4e3199e <unknown>
E   #3 0x5597f4e31aa1 <unknown>
E   #4 0x5597f4e7cd64 <unknown>
E   #5 0x5597f4e5b0dd <unknown>
E   #6 0x5597f4e7a006 <unknown>
E   #7 0x5597f4e5ae53 <unknown>
E   #8 0x5597f4e22dd4 <unknown>
E   #9 0x5597f4e241de <unknown>
E   #10 0x5597f50ed531 <unknown>
E   #11 0x5597f50f1455 <unknown>
E   #12 0x5597f50d9f55 <unknown>
E   #13 0x5597f50f20ef <unknown>
E   #14 0x5597f50bd99f <unknown>
E   #15 0x5597f5116008 <unknown>
E   #16 0x5597f51161d7 <unknown>
E   #17 0x5597f5128124 <unknown>
E   #18 0x7f6f2627eac3 <unknown>

During handling of the above exception, another exception occurred:
test_selenium_mc.py:338: in test_click_fith_button
    raise Exception(f"Failed to find or click the fourth button (class: {button_class}).")
E   Exception: Failed to find or click the fourth button (class: btn.btn-primary.svelte-1pvzwgg).
________________________ test_grab_terminal_output_two _________________________
test_selenium_mc.py:368: in test_grab_terminal_output_two
    terminal_output_element = WebDriverWait(driver, 10).until(
../../../.local/lib/python3.8/site-packages/selenium/webdriver/support/wait.py:101: in until
    raise TimeoutException(message, screen, stacktrace)
E   selenium.common.exceptions.TimeoutException: Message: 
E   Stacktrace:
E   #0 0x5597f5128f83 <unknown>
E   #1 0x5597f4de1cf7 <unknown>
E   #2 0x5597f4e3199e <unknown>
E   #3 0x5597f4e31aa1 <unknown>
E   #4 0x5597f4e7cd64 <unknown>
E   #5 0x5597f4e5b0dd <unknown>
E   #6 0x5597f4e7a006 <unknown>
E   #7 0x5597f4e5ae53 <unknown>
E   #8 0x5597f4e22dd4 <unknown>
E   #9 0x5597f4e241de <unknown>
E   #10 0x5597f50ed531 <unknown>
E   #11 0x5597f50f1455 <unknown>
E   #12 0x5597f50d9f55 <unknown>
E   #13 0x5597f50f20ef <unknown>
E   #14 0x5597f50bd99f <unknown>
E   #15 0x5597f5116008 <unknown>
E   #16 0x5597f51161d7 <unknown>
E   #17 0x5597f5128124 <unknown>
E   #18 0x7f6f2627eac3 <unknown>

During handling of the above exception, another exception occurred:
test_selenium_mc.py:372: in test_grab_terminal_output_two
    raise Exception("Failed to find or load the terminal output element within the specified time.")
E   Exception: Failed to find or load the terminal output element within the specified time.
=========================== short test summary info ============================
FAILED test_selenium_mc.py::test_login_to_mc_console - AssertionError: The pa...
FAILED test_selenium_mc.py::test_initiate_core_setup - Exception: Failed to n...
FAILED test_selenium_mc.py::test_input_venue_name - Exception: Failed to find...
FAILED test_selenium_mc.py::test_input_project_name - Exception: Failed to fi...
FAILED test_selenium_mc.py::test_core_setup_save_btn - Exception: Failed to f...
FAILED test_selenium_mc.py::test_return_to_marketplace - Exception: Failed to...
FAILED test_selenium_mc.py::test_grab_terminal_output - Exception: Failed to ...
FAILED test_selenium_mc.py::test_install_eks - Exception: Failed to install E...
FAILED test_selenium_mc.py::test_eks_module_name - Exception: Textbox for mod...
FAILED test_selenium_mc.py::test_eks_module_branch - Exception: Textbox for b...
FAILED test_selenium_mc.py::test_click_first_button - Exception: Failed to fi...
FAILED test_selenium_mc.py::test_click_second_button - Exception: Failed to f...
FAILED test_selenium_mc.py::test_click_third_button - Exception: Failed to fi...
FAILED test_selenium_mc.py::test_click_fourth_button - Exception: Failed to f...
FAILED test_selenium_mc.py::test_click_fith_button - Exception: Failed to fin...
FAILED test_selenium_mc.py::test_grab_terminal_output_two - Exception: Failed...
=================== 16 failed, 1 passed in 200.68s (0:03:20) ===================
============================= test session starts ==============================
platform linux -- Python 3.8.10, pytest-7.4.3, pluggy-1.3.0 -- /usr/bin/python3
cachedir: .pytest_cache
rootdir: /home/ubuntu/unity-cs-infra/nightly_tests/nightly_tests_ondemand
collecting ... collected 17 items

test_selenium_mc.py::test_navigate_to_url_with_cred FAILED               [  5%]
test_selenium_mc.py::test_login_to_mc_console FAILED                     [ 11%]
test_selenium_mc.py::test_initiate_core_setup FAILED                     [ 17%]
test_selenium_mc.py::test_input_venue_name FAILED                        [ 23%]
test_selenium_mc.py::test_input_project_name FAILED                      [ 29%]
test_selenium_mc.py::test_core_setup_save_btn FAILED                     [ 35%]
test_selenium_mc.py::test_return_to_marketplace FAILED                   [ 41%]
test_selenium_mc.py::test_grab_terminal_output FAILED                    [ 47%]
test_selenium_mc.py::test_install_eks FAILED                             [ 52%]
test_selenium_mc.py::test_eks_module_name FAILED                         [ 58%]
test_selenium_mc.py::test_eks_module_branch FAILED                       [ 64%]
test_selenium_mc.py::test_click_first_button FAILED                      [ 70%]
test_selenium_mc.py::test_click_second_button FAILED                     [ 76%]
test_selenium_mc.py::test_click_third_button FAILED                      [ 82%]
test_selenium_mc.py::test_click_fourth_button FAILED                     [ 88%]
test_selenium_mc.py::test_click_fith_button FAILED                       [ 94%]
test_selenium_mc.py::test_grab_terminal_output_two FAILED                [100%]

=================================== FAILURES ===================================
________________________ test_navigate_to_url_with_cred ________________________
test_selenium_mc.py:47: in test_navigate_to_url_with_cred
    driver.get(URL_WITH_CRED)
../../../.local/lib/python3.8/site-packages/selenium/webdriver/remote/webdriver.py:356: in get
    self.execute(Command.GET, {"url": url})
../../../.local/lib/python3.8/site-packages/selenium/webdriver/remote/webdriver.py:347: in execute
    self.error_handler.check_response(response)
../../../.local/lib/python3.8/site-packages/selenium/webdriver/remote/errorhandler.py:229: in check_response
    raise exception_class(message, screen, stacktrace)
E   selenium.common.exceptions.WebDriverException: Message: unknown error: net::ERR_NAME_NOT_RESOLVED
E     (Session info: chrome=120.0.6099.109)
E   Stacktrace:
E   #0 0x558d5289cf83 <unknown>
E   #1 0x558d52555cf7 <unknown>
E   #2 0x558d5254d6ea <unknown>
E   #3 0x558d5253c5a1 <unknown>
E   #4 0x558d5253dd40 <unknown>
E   #5 0x558d5253c854 <unknown>
E   #6 0x558d5253b586 <unknown>
E   #7 0x558d5253b44a <unknown>
E   #8 0x558d525397e1 <unknown>
E   #9 0x558d5253a01a <unknown>
E   #10 0x558d52558bbe <unknown>
E   #11 0x558d525ee7a5 <unknown>
E   #12 0x558d525cf0b2 <unknown>
E   #13 0x558d525ee006 <unknown>
E   #14 0x558d525cee53 <unknown>
E   #15 0x558d52596dd4 <unknown>
E   #16 0x558d525981de <unknown>
E   #17 0x558d52861531 <unknown>
E   #18 0x558d52865455 <unknown>
E   #19 0x558d5284df55 <unknown>
E   #20 0x558d528660ef <unknown>
E   #21 0x558d5283199f <unknown>
E   #22 0x558d5288a008 <unknown>
E   #23 0x558d5288a1d7 <unknown>
E   #24 0x558d5289c124 <unknown>
E   #25 0x7f6e04478ac3 <unknown>
___________________________ test_login_to_mc_console ___________________________
test_selenium_mc.py:72: in test_login_to_mc_console
    assert driver.title == 'Unity Management Console', "The page title should be Unity Management Console"
E   AssertionError: The page title should be Unity Management Console
E   assert 'unity-on-dem...amazonaws.com' == 'Unity Management Console'
E     - Unity Management Console
E     + unity-on-demand-alb-ceqmr-441279383.us-west-2.elb.amazonaws.com
___________________________ test_initiate_core_setup ___________________________
test_selenium_mc.py:78: in test_initiate_core_setup
    go_button = WebDriverWait(driver, 20).until(
../../../.local/lib/python3.8/site-packages/selenium/webdriver/support/wait.py:101: in until
    raise TimeoutException(message, screen, stacktrace)
E   selenium.common.exceptions.TimeoutException: Message: 
E   Stacktrace:
E   #0 0x558d5289cf83 <unknown>
E   #1 0x558d52555cf7 <unknown>
E   #2 0x558d525a599e <unknown>
E   #3 0x558d525a5aa1 <unknown>
E   #4 0x558d525f0d64 <unknown>
E   #5 0x558d525cf0dd <unknown>
E   #6 0x558d525ee006 <unknown>
E   #7 0x558d525cee53 <unknown>
E   #8 0x558d52596dd4 <unknown>
E   #9 0x558d525981de <unknown>
E   #10 0x558d52861531 <unknown>
E   #11 0x558d52865455 <unknown>
E   #12 0x558d5284df55 <unknown>
E   #13 0x558d528660ef <unknown>
E   #14 0x558d5283199f <unknown>
E   #15 0x558d5288a008 <unknown>
E   #16 0x558d5288a1d7 <unknown>
E   #17 0x558d5289c124 <unknown>
E   #18 0x7f6e04478ac3 <unknown>

During handling of the above exception, another exception occurred:
test_selenium_mc.py:87: in test_initiate_core_setup
    raise Exception("Failed to navigate to setup page - either the Go button was not clickable or the URL did not change as expected.")
E   Exception: Failed to navigate to setup page - either the Go button was not clickable or the URL did not change as expected.
____________________________ test_input_venue_name _____________________________
test_selenium_mc.py:102: in test_input_venue_name
    text_box = WebDriverWait(driver, 10).until(
../../../.local/lib/python3.8/site-packages/selenium/webdriver/support/wait.py:101: in until
    raise TimeoutException(message, screen, stacktrace)
E   selenium.common.exceptions.TimeoutException: Message: 
E   Stacktrace:
E   #0 0x558d5289cf83 <unknown>
E   #1 0x558d52555cf7 <unknown>
E   #2 0x558d525a599e <unknown>
E   #3 0x558d525a5aa1 <unknown>
E   #4 0x558d525f0d64 <unknown>
E   #5 0x558d525cf0dd <unknown>
E   #6 0x558d525ee006 <unknown>
E   #7 0x558d525cee53 <unknown>
E   #8 0x558d52596dd4 <unknown>
E   #9 0x558d525981de <unknown>
E   #10 0x558d52861531 <unknown>
E   #11 0x558d52865455 <unknown>
E   #12 0x558d5284df55 <unknown>
E   #13 0x558d528660ef <unknown>
E   #14 0x558d5283199f <unknown>
E   #15 0x558d5288a008 <unknown>
E   #16 0x558d5288a1d7 <unknown>
E   #17 0x558d5289c124 <unknown>
E   #18 0x7f6e04478ac3 <unknown>

During handling of the above exception, another exception occurred:
test_selenium_mc.py:109: in test_input_venue_name
    raise Exception(f"Failed to find or interact with the text box for venue name (ID: {element_id}).")
E   Exception: Failed to find or interact with the text box for venue name (ID: venue).
___________________________ test_input_project_name ____________________________
test_selenium_mc.py:124: in test_input_project_name
    text_box = WebDriverWait(driver, 10).until(
../../../.local/lib/python3.8/site-packages/selenium/webdriver/support/wait.py:101: in until
    raise TimeoutException(message, screen, stacktrace)
E   selenium.common.exceptions.TimeoutException: Message: 
E   Stacktrace:
E   #0 0x558d5289cf83 <unknown>
E   #1 0x558d52555cf7 <unknown>
E   #2 0x558d525a599e <unknown>
E   #3 0x558d525a5aa1 <unknown>
E   #4 0x558d525f0d64 <unknown>
E   #5 0x558d525cf0dd <unknown>
E   #6 0x558d525ee006 <unknown>
E   #7 0x558d525cee53 <unknown>
E   #8 0x558d52596dd4 <unknown>
E   #9 0x558d525981de <unknown>
E   #10 0x558d52861531 <unknown>
E   #11 0x558d52865455 <unknown>
E   #12 0x558d5284df55 <unknown>
E   #13 0x558d528660ef <unknown>
E   #14 0x558d5283199f <unknown>
E   #15 0x558d5288a008 <unknown>
E   #16 0x558d5288a1d7 <unknown>
E   #17 0x558d5289c124 <unknown>
E   #18 0x7f6e04478ac3 <unknown>

During handling of the above exception, another exception occurred:
test_selenium_mc.py:131: in test_input_project_name
    raise Exception(f"Failed to find or interact with the text box for project name (ID: {element_id}).")
E   Exception: Failed to find or interact with the text box for project name (ID: project).
___________________________ test_core_setup_save_btn ___________________________
test_selenium_mc.py:144: in test_core_setup_save_btn
    save_button = WebDriverWait(driver, 10).until(
../../../.local/lib/python3.8/site-packages/selenium/webdriver/support/wait.py:101: in until
    raise TimeoutException(message, screen, stacktrace)
E   selenium.common.exceptions.TimeoutException: Message: 
E   Stacktrace:
E   #0 0x558d5289cf83 <unknown>
E   #1 0x558d52555cf7 <unknown>
E   #2 0x558d525a599e <unknown>
E   #3 0x558d525a5aa1 <unknown>
E   #4 0x558d525f0d64 <unknown>
E   #5 0x558d525cf0dd <unknown>
E   #6 0x558d525ee006 <unknown>
E   #7 0x558d525cee53 <unknown>
E   #8 0x558d52596dd4 <unknown>
E   #9 0x558d525981de <unknown>
E   #10 0x558d52861531 <unknown>
E   #11 0x558d52865455 <unknown>
E   #12 0x558d5284df55 <unknown>
E   #13 0x558d528660ef <unknown>
E   #14 0x558d5283199f <unknown>
E   #15 0x558d5288a008 <unknown>
E   #16 0x558d5288a1d7 <unknown>
E   #17 0x558d5289c124 <unknown>
E   #18 0x7f6e04478ac3 <unknown>

During handling of the above exception, another exception occurred:
test_selenium_mc.py:150: in test_core_setup_save_btn
    raise Exception("Failed to find or click the core'Save' button within the specified time.")
E   Exception: Failed to find or click the core'Save' button within the specified time.
__________________________ test_return_to_marketplace __________________________
test_selenium_mc.py:158: in test_return_to_marketplace
    driver.get(url_without_cred)
../../../.local/lib/python3.8/site-packages/selenium/webdriver/remote/webdriver.py:356: in get
    self.execute(Command.GET, {"url": url})
../../../.local/lib/python3.8/site-packages/selenium/webdriver/remote/webdriver.py:347: in execute
    self.error_handler.check_response(response)
../../../.local/lib/python3.8/site-packages/selenium/webdriver/remote/errorhandler.py:229: in check_response
    raise exception_class(message, screen, stacktrace)
E   selenium.common.exceptions.WebDriverException: Message: unknown error: net::ERR_NAME_NOT_RESOLVED
E     (Session info: chrome=120.0.6099.109)
E   Stacktrace:
E   #0 0x558d5289cf83 <unknown>
E   #1 0x558d52555cf7 <unknown>
E   #2 0x558d5254d6ea <unknown>
E   #3 0x558d5253c5a1 <unknown>
E   #4 0x558d5253dd40 <unknown>
E   #5 0x558d5253c854 <unknown>
E   #6 0x558d5253b586 <unknown>
E   #7 0x558d5253b44a <unknown>
E   #8 0x558d525397e1 <unknown>
E   #9 0x558d5253a01a <unknown>
E   #10 0x558d52558bbe <unknown>
E   #11 0x558d525ee7a5 <unknown>
E   #12 0x558d525cf0b2 <unknown>
E   #13 0x558d525ee006 <unknown>
E   #14 0x558d525cee53 <unknown>
E   #15 0x558d52596dd4 <unknown>
E   #16 0x558d525981de <unknown>
E   #17 0x558d52861531 <unknown>
E   #18 0x558d52865455 <unknown>
E   #19 0x558d5284df55 <unknown>
E   #20 0x558d528660ef <unknown>
E   #21 0x558d5283199f <unknown>
E   #22 0x558d5288a008 <unknown>
E   #23 0x558d5288a1d7 <unknown>
E   #24 0x558d5289c124 <unknown>
E   #25 0x7f6e04478ac3 <unknown>
__________________________ test_grab_terminal_output ___________________________
test_selenium_mc.py:193: in test_grab_terminal_output
    terminal_output_element = WebDriverWait(driver, 10).until(
../../../.local/lib/python3.8/site-packages/selenium/webdriver/support/wait.py:101: in until
    raise TimeoutException(message, screen, stacktrace)
E   selenium.common.exceptions.TimeoutException: Message: 
E   Stacktrace:
E   #0 0x558d5289cf83 <unknown>
E   #1 0x558d52555cf7 <unknown>
E   #2 0x558d525a599e <unknown>
E   #3 0x558d525a5aa1 <unknown>
E   #4 0x558d525f0d64 <unknown>
E   #5 0x558d525cf0dd <unknown>
E   #6 0x558d525ee006 <unknown>
E   #7 0x558d525cee53 <unknown>
E   #8 0x558d52596dd4 <unknown>
E   #9 0x558d525981de <unknown>
E   #10 0x558d52861531 <unknown>
E   #11 0x558d52865455 <unknown>
E   #12 0x558d5284df55 <unknown>
E   #13 0x558d528660ef <unknown>
E   #14 0x558d5283199f <unknown>
E   #15 0x558d5288a008 <unknown>
E   #16 0x558d5288a1d7 <unknown>
E   #17 0x558d5289c124 <unknown>
E   #18 0x7f6e04478ac3 <unknown>

During handling of the above exception, another exception occurred:
test_selenium_mc.py:198: in test_grab_terminal_output
    raise Exception("Failed to find or load the terminal output element within the specified time.")
E   Exception: Failed to find or load the terminal output element within the specified time.
_______________________________ test_install_eks _______________________________
test_selenium_mc.py:213: in test_install_eks
    install_button = WebDriverWait(driver, 10).until(
../../../.local/lib/python3.8/site-packages/selenium/webdriver/support/wait.py:101: in until
    raise TimeoutException(message, screen, stacktrace)
E   selenium.common.exceptions.TimeoutException: Message: 
E   Stacktrace:
E   #0 0x558d5289cf83 <unknown>
E   #1 0x558d52555cf7 <unknown>
E   #2 0x558d525a599e <unknown>
E   #3 0x558d525a5aa1 <unknown>
E   #4 0x558d525f0d64 <unknown>
E   #5 0x558d525cf0dd <unknown>
E   #6 0x558d525ee006 <unknown>
E   #7 0x558d525cee53 <unknown>
E   #8 0x558d52596dd4 <unknown>
E   #9 0x558d525981de <unknown>
E   #10 0x558d52861531 <unknown>
E   #11 0x558d52865455 <unknown>
E   #12 0x558d5284df55 <unknown>
E   #13 0x558d528660ef <unknown>
E   #14 0x558d5283199f <unknown>
E   #15 0x558d5288a008 <unknown>
E   #16 0x558d5288a1d7 <unknown>
E   #17 0x558d5289c124 <unknown>
E   #18 0x7f6e04478ac3 <unknown>

During handling of the above exception, another exception occurred:
test_selenium_mc.py:222: in test_install_eks
    raise Exception("Failed to install EKS - either the button was not clickable or the URL did not update as expected.")
E   Exception: Failed to install EKS - either the button was not clickable or the URL did not update as expected.
_____________________________ test_eks_module_name _____________________________
test_selenium_mc.py:234: in test_eks_module_name
    text_box = WebDriverWait(driver, 10).until(
../../../.local/lib/python3.8/site-packages/selenium/webdriver/support/wait.py:101: in until
    raise TimeoutException(message, screen, stacktrace)
E   selenium.common.exceptions.TimeoutException: Message: 
E   Stacktrace:
E   #0 0x558d5289cf83 <unknown>
E   #1 0x558d52555cf7 <unknown>
E   #2 0x558d525a599e <unknown>
E   #3 0x558d525a5aa1 <unknown>
E   #4 0x558d525f0d64 <unknown>
E   #5 0x558d525cf0dd <unknown>
E   #6 0x558d525ee006 <unknown>
E   #7 0x558d525cee53 <unknown>
E   #8 0x558d52596dd4 <unknown>
E   #9 0x558d525981de <unknown>
E   #10 0x558d52861531 <unknown>
E   #11 0x558d52865455 <unknown>
E   #12 0x558d5284df55 <unknown>
E   #13 0x558d528660ef <unknown>
E   #14 0x558d5283199f <unknown>
E   #15 0x558d5288a008 <unknown>
E   #16 0x558d5288a1d7 <unknown>
E   #17 0x558d5289c124 <unknown>
E   #18 0x7f6e04478ac3 <unknown>

During handling of the above exception, another exception occurred:
test_selenium_mc.py:238: in test_eks_module_name
    raise Exception(f"Textbox for module name (ID: {element_id}) not found.")
E   Exception: Textbox for module name (ID: module) not found.
____________________________ test_eks_module_branch ____________________________
test_selenium_mc.py:252: in test_eks_module_branch
    text_box = WebDriverWait(driver, 10).until(
../../../.local/lib/python3.8/site-packages/selenium/webdriver/support/wait.py:101: in until
    raise TimeoutException(message, screen, stacktrace)
E   selenium.common.exceptions.TimeoutException: Message: 
E   Stacktrace:
E   #0 0x558d5289cf83 <unknown>
E   #1 0x558d52555cf7 <unknown>
E   #2 0x558d525a599e <unknown>
E   #3 0x558d525a5aa1 <unknown>
E   #4 0x558d525f0d64 <unknown>
E   #5 0x558d525cf0dd <unknown>
E   #6 0x558d525ee006 <unknown>
E   #7 0x558d525cee53 <unknown>
E   #8 0x558d52596dd4 <unknown>
E   #9 0x558d525981de <unknown>
E   #10 0x558d52861531 <unknown>
E   #11 0x558d52865455 <unknown>
E   #12 0x558d5284df55 <unknown>
E   #13 0x558d528660ef <unknown>
E   #14 0x558d5283199f <unknown>
E   #15 0x558d5288a008 <unknown>
E   #16 0x558d5288a1d7 <unknown>
E   #17 0x558d5289c124 <unknown>
E   #18 0x7f6e04478ac3 <unknown>

During handling of the above exception, another exception occurred:
test_selenium_mc.py:256: in test_eks_module_branch
    raise Exception(f"Textbox for branch name (ID: {element_id}) not found.")
E   Exception: Textbox for branch name (ID: branch) not found.
___________________________ test_click_first_button ____________________________
test_selenium_mc.py:269: in test_click_first_button
    button = WebDriverWait(driver, 10).until(
../../../.local/lib/python3.8/site-packages/selenium/webdriver/support/wait.py:101: in until
    raise TimeoutException(message, screen, stacktrace)
E   selenium.common.exceptions.TimeoutException: Message: 
E   Stacktrace:
E   #0 0x558d5289cf83 <unknown>
E   #1 0x558d52555cf7 <unknown>
E   #2 0x558d525a599e <unknown>
E   #3 0x558d525a5aa1 <unknown>
E   #4 0x558d525f0d64 <unknown>
E   #5 0x558d525cf0dd <unknown>
E   #6 0x558d525ee006 <unknown>
E   #7 0x558d525cee53 <unknown>
E   #8 0x558d52596dd4 <unknown>
E   #9 0x558d525981de <unknown>
E   #10 0x558d52861531 <unknown>
E   #11 0x558d52865455 <unknown>
E   #12 0x558d5284df55 <unknown>
E   #13 0x558d528660ef <unknown>
E   #14 0x558d5283199f <unknown>
E   #15 0x558d5288a008 <unknown>
E   #16 0x558d5288a1d7 <unknown>
E   #17 0x558d5289c124 <unknown>
E   #18 0x7f6e04478ac3 <unknown>

During handling of the above exception, another exception occurred:
test_selenium_mc.py:274: in test_click_first_button
    raise Exception(f"Failed to find or click the first button (class: {button_class}).")
E   Exception: Failed to find or click the first button (class: default-btn.next-step.svelte-1pvzwgg).
___________________________ test_click_second_button ___________________________
test_selenium_mc.py:285: in test_click_second_button
    button = WebDriverWait(driver, 10).until(
../../../.local/lib/python3.8/site-packages/selenium/webdriver/support/wait.py:101: in until
    raise TimeoutException(message, screen, stacktrace)
E   selenium.common.exceptions.TimeoutException: Message: 
E   Stacktrace:
E   #0 0x558d5289cf83 <unknown>
E   #1 0x558d52555cf7 <unknown>
E   #2 0x558d525a599e <unknown>
E   #3 0x558d525a5aa1 <unknown>
E   #4 0x558d525f0d64 <unknown>
E   #5 0x558d525cf0dd <unknown>
E   #6 0x558d525ee006 <unknown>
E   #7 0x558d525cee53 <unknown>
E   #8 0x558d52596dd4 <unknown>
E   #9 0x558d525981de <unknown>
E   #10 0x558d52861531 <unknown>
E   #11 0x558d52865455 <unknown>
E   #12 0x558d5284df55 <unknown>
E   #13 0x558d528660ef <unknown>
E   #14 0x558d5283199f <unknown>
E   #15 0x558d5288a008 <unknown>
E   #16 0x558d5288a1d7 <unknown>
E   #17 0x558d5289c124 <unknown>
E   #18 0x7f6e04478ac3 <unknown>

During handling of the above exception, another exception occurred:
test_selenium_mc.py:290: in test_click_second_button
    raise Exception(f"Failed to find or click the second button (class: {button_class}).")
E   Exception: Failed to find or click the second button (class: default-btn.next-step.svelte-1pvzwgg).
___________________________ test_click_third_button ____________________________
test_selenium_mc.py:301: in test_click_third_button
    button = WebDriverWait(driver, 10).until(
../../../.local/lib/python3.8/site-packages/selenium/webdriver/support/wait.py:101: in until
    raise TimeoutException(message, screen, stacktrace)
E   selenium.common.exceptions.TimeoutException: Message: 
E   Stacktrace:
E   #0 0x558d5289cf83 <unknown>
E   #1 0x558d52555cf7 <unknown>
E   #2 0x558d525a599e <unknown>
E   #3 0x558d525a5aa1 <unknown>
E   #4 0x558d525f0d64 <unknown>
E   #5 0x558d525cf0dd <unknown>
E   #6 0x558d525ee006 <unknown>
E   #7 0x558d525cee53 <unknown>
E   #8 0x558d52596dd4 <unknown>
E   #9 0x558d525981de <unknown>
E   #10 0x558d52861531 <unknown>
E   #11 0x558d52865455 <unknown>
E   #12 0x558d5284df55 <unknown>
E   #13 0x558d528660ef <unknown>
E   #14 0x558d5283199f <unknown>
E   #15 0x558d5288a008 <unknown>
E   #16 0x558d5288a1d7 <unknown>
E   #17 0x558d5289c124 <unknown>
E   #18 0x7f6e04478ac3 <unknown>

During handling of the above exception, another exception occurred:
test_selenium_mc.py:306: in test_click_third_button
    raise Exception(f"Failed to find or click the third button (class: {button_class}).")
E   Exception: Failed to find or click the third button (class: default-btn.next-step.svelte-1pvzwgg).
___________________________ test_click_fourth_button ___________________________
test_selenium_mc.py:350: in test_click_fourth_button
    button = WebDriverWait(driver, 10).until(
../../../.local/lib/python3.8/site-packages/selenium/webdriver/support/wait.py:101: in until
    raise TimeoutException(message, screen, stacktrace)
E   selenium.common.exceptions.TimeoutException: Message: 
E   Stacktrace:
E   #0 0x558d5289cf83 <unknown>
E   #1 0x558d52555cf7 <unknown>
E   #2 0x558d525a599e <unknown>
E   #3 0x558d525a5aa1 <unknown>
E   #4 0x558d525f0d64 <unknown>
E   #5 0x558d525cf0dd <unknown>
E   #6 0x558d525ee006 <unknown>
E   #7 0x558d525cee53 <unknown>
E   #8 0x558d52596dd4 <unknown>
E   #9 0x558d525981de <unknown>
E   #10 0x558d52861531 <unknown>
E   #11 0x558d52865455 <unknown>
E   #12 0x558d5284df55 <unknown>
E   #13 0x558d528660ef <unknown>
E   #14 0x558d5283199f <unknown>
E   #15 0x558d5288a008 <unknown>
E   #16 0x558d5288a1d7 <unknown>
E   #17 0x558d5289c124 <unknown>
E   #18 0x7f6e04478ac3 <unknown>

During handling of the above exception, another exception occurred:
test_selenium_mc.py:355: in test_click_fourth_button
    raise Exception(f"Failed to find or click the fourth button (class: {button_class}).")
E   Exception: Failed to find or click the fourth button (class: btn.btn-primary.svelte-1pvzwgg).
____________________________ test_click_fith_button ____________________________
test_selenium_mc.py:333: in test_click_fith_button
    button = WebDriverWait(driver, 10).until(
../../../.local/lib/python3.8/site-packages/selenium/webdriver/support/wait.py:101: in until
    raise TimeoutException(message, screen, stacktrace)
E   selenium.common.exceptions.TimeoutException: Message: 
E   Stacktrace:
E   #0 0x558d5289cf83 <unknown>
E   #1 0x558d52555cf7 <unknown>
E   #2 0x558d525a599e <unknown>
E   #3 0x558d525a5aa1 <unknown>
E   #4 0x558d525f0d64 <unknown>
E   #5 0x558d525cf0dd <unknown>
E   #6 0x558d525ee006 <unknown>
E   #7 0x558d525cee53 <unknown>
E   #8 0x558d52596dd4 <unknown>
E   #9 0x558d525981de <unknown>
E   #10 0x558d52861531 <unknown>
E   #11 0x558d52865455 <unknown>
E   #12 0x558d5284df55 <unknown>
E   #13 0x558d528660ef <unknown>
E   #14 0x558d5283199f <unknown>
E   #15 0x558d5288a008 <unknown>
E   #16 0x558d5288a1d7 <unknown>
E   #17 0x558d5289c124 <unknown>
E   #18 0x7f6e04478ac3 <unknown>

During handling of the above exception, another exception occurred:
test_selenium_mc.py:338: in test_click_fith_button
    raise Exception(f"Failed to find or click the fourth button (class: {button_class}).")
E   Exception: Failed to find or click the fourth button (class: btn.btn-primary.svelte-1pvzwgg).
________________________ test_grab_terminal_output_two _________________________
test_selenium_mc.py:368: in test_grab_terminal_output_two
    terminal_output_element = WebDriverWait(driver, 10).until(
../../../.local/lib/python3.8/site-packages/selenium/webdriver/support/wait.py:101: in until
    raise TimeoutException(message, screen, stacktrace)
E   selenium.common.exceptions.TimeoutException: Message: 
E   Stacktrace:
E   #0 0x558d5289cf83 <unknown>
E   #1 0x558d52555cf7 <unknown>
E   #2 0x558d525a599e <unknown>
E   #3 0x558d525a5aa1 <unknown>
E   #4 0x558d525f0d64 <unknown>
E   #5 0x558d525cf0dd <unknown>
E   #6 0x558d525ee006 <unknown>
E   #7 0x558d525cee53 <unknown>
E   #8 0x558d52596dd4 <unknown>
E   #9 0x558d525981de <unknown>
E   #10 0x558d52861531 <unknown>
E   #11 0x558d52865455 <unknown>
E   #12 0x558d5284df55 <unknown>
E   #13 0x558d528660ef <unknown>
E   #14 0x558d5283199f <unknown>
E   #15 0x558d5288a008 <unknown>
E   #16 0x558d5288a1d7 <unknown>
E   #17 0x558d5289c124 <unknown>
E   #18 0x7f6e04478ac3 <unknown>

During handling of the above exception, another exception occurred:
test_selenium_mc.py:372: in test_grab_terminal_output_two
    raise Exception("Failed to find or load the terminal output element within the specified time.")
E   Exception: Failed to find or load the terminal output element within the specified time.
=========================== short test summary info ============================
FAILED test_selenium_mc.py::test_navigate_to_url_with_cred - selenium.common....
FAILED test_selenium_mc.py::test_login_to_mc_console - AssertionError: The pa...
FAILED test_selenium_mc.py::test_initiate_core_setup - Exception: Failed to n...
FAILED test_selenium_mc.py::test_input_venue_name - Exception: Failed to find...
FAILED test_selenium_mc.py::test_input_project_name - Exception: Failed to fi...
FAILED test_selenium_mc.py::test_core_setup_save_btn - Exception: Failed to f...
FAILED test_selenium_mc.py::test_return_to_marketplace - selenium.common.exce...
FAILED test_selenium_mc.py::test_grab_terminal_output - Exception: Failed to ...
FAILED test_selenium_mc.py::test_install_eks - Exception: Failed to install E...
FAILED test_selenium_mc.py::test_eks_module_name - Exception: Textbox for mod...
FAILED test_selenium_mc.py::test_eks_module_branch - Exception: Textbox for b...
FAILED test_selenium_mc.py::test_click_first_button - Exception: Failed to fi...
FAILED test_selenium_mc.py::test_click_second_button - Exception: Failed to f...
FAILED test_selenium_mc.py::test_click_third_button - Exception: Failed to fi...
FAILED test_selenium_mc.py::test_click_fourth_button - Exception: Failed to f...
FAILED test_selenium_mc.py::test_click_fith_button - Exception: Failed to fin...
FAILED test_selenium_mc.py::test_grab_terminal_output_two - Exception: Failed...
======================== 17 failed in 171.35s (0:02:51) ========================
