Repo Hash (Nightly Test):     [6686d95]
Deploying Cloudformation stack...
Marketplace Items:
Marketplace Item                | Version
--------------------------------+--------
unity-cs-monitoring-lambda      | 0.1
unity-apigateway                | 0.4
unity-proxy                     | 0.14
Nightly Test in the (TODO FIXME) account
Stack Name: [unity-management-console-unity-nightly]
Cloudformation Stack creation exceeded 2400 seconds - [FAIL]
Deploying Management Console...
============================= test session starts ==============================
platform linux -- Python 3.8.10, pytest-8.3.2, pluggy-1.5.0 -- /usr/bin/python3
cachedir: .pytest_cache
rootdir: /home/ubuntu/unity-cs-infra/nightly_tests
collecting ... collected 4 items

test_selenium_mc.py::test_navigate_to_mc_console FAILED                  [ 25%]
test_selenium_mc.py::test_bootstrap_process_status FAILED                [ 50%]
test_selenium_mc.py::test_initiate_core_setup FAILED                     [ 75%]
test_selenium_mc.py::test_core_setup_save_btn FAILED                     [100%]

=================================== FAILURES ===================================
_________________________ test_navigate_to_mc_console __________________________
test_selenium_mc.py:56: in test_navigate_to_mc_console
    driver.get(URL_WITHOUT_CRED)
../../.local/lib/python3.8/site-packages/selenium/webdriver/remote/webdriver.py:363: in get
    self.execute(Command.GET, {"url": url})
../../.local/lib/python3.8/site-packages/selenium/webdriver/remote/webdriver.py:354: in execute
    self.error_handler.check_response(response)
../../.local/lib/python3.8/site-packages/selenium/webdriver/remote/errorhandler.py:229: in check_response
    raise exception_class(message, screen, stacktrace)
E   selenium.common.exceptions.InvalidArgumentException: Message: invalid argument
E     (Session info: chrome=130.0.6723.91)
E   Stacktrace:
E   #0 0x562b64b3513a <unknown>
E   #1 0x562b646502bd <unknown>
E   #2 0x562b6463816f <unknown>
E   #3 0x562b646367c8 <unknown>
E   #4 0x562b64636eba <unknown>
E   #5 0x562b64652d59 <unknown>
E   #6 0x562b646e0645 <unknown>
E   #7 0x562b646c1012 <unknown>
E   #8 0x562b646dfaf6 <unknown>
E   #9 0x562b646c0db3 <unknown>
E   #10 0x562b6468fc10 <unknown>
E   #11 0x562b64690bee <unknown>
E   #12 0x562b64b013cb <unknown>
E   #13 0x562b64b05368 <unknown>
E   #14 0x562b64aeeeec <unknown>
E   #15 0x562b64b05ee7 <unknown>
E   #16 0x562b64ad413f <unknown>
E   #17 0x562b64b23858 <unknown>
E   #18 0x562b64b23a20 <unknown>
E   #19 0x562b64b33fb6 <unknown>
E   #20 0x7fc9f3955a94 <unknown>
E   #21 0x7fc9f39e2a34 __clone
________________________ test_bootstrap_process_status _________________________
test_selenium_mc.py:77: in test_bootstrap_process_status
    bootstrap_status_element = WebDriverWait(driver, 10).until(
../../.local/lib/python3.8/site-packages/selenium/webdriver/support/wait.py:105: in until
    raise TimeoutException(message, screen, stacktrace)
E   selenium.common.exceptions.TimeoutException: Message: 
E   Stacktrace:
E   #0 0x562b64b3513a <unknown>
E   #1 0x562b64650460 <unknown>
E   #2 0x562b6469cf96 <unknown>
E   #3 0x562b6469d221 <unknown>
E   #4 0x562b646e25d4 <unknown>
E   #5 0x562b646c103d <unknown>
E   #6 0x562b646dfaf6 <unknown>
E   #7 0x562b646c0db3 <unknown>
E   #8 0x562b6468fc10 <unknown>
E   #9 0x562b64690bee <unknown>
E   #10 0x562b64b013cb <unknown>
E   #11 0x562b64b05368 <unknown>
E   #12 0x562b64aeeeec <unknown>
E   #13 0x562b64b05ee7 <unknown>
E   #14 0x562b64ad413f <unknown>
E   #15 0x562b64b23858 <unknown>
E   #16 0x562b64b23a20 <unknown>
E   #17 0x562b64b33fb6 <unknown>
E   #18 0x7fc9f3955a94 <unknown>
E   #19 0x7fc9f39e2a34 __clone

During handling of the above exception, another exception occurred:
test_selenium_mc.py:89: in test_bootstrap_process_status
    raise Exception("Failed to find the bootstrap status message within the specified time.")
E   Exception: Failed to find the bootstrap status message within the specified time.
___________________________ test_initiate_core_setup ___________________________
test_selenium_mc.py:95: in test_initiate_core_setup
    go_button = WebDriverWait(driver, 20).until(
../../.local/lib/python3.8/site-packages/selenium/webdriver/support/wait.py:105: in until
    raise TimeoutException(message, screen, stacktrace)
E   selenium.common.exceptions.TimeoutException: Message: 
E   Stacktrace:
E   #0 0x562b64b3513a <unknown>
E   #1 0x562b64650460 <unknown>
E   #2 0x562b6469cf96 <unknown>
E   #3 0x562b6469d221 <unknown>
E   #4 0x562b646e25d4 <unknown>
E   #5 0x562b646c103d <unknown>
E   #6 0x562b646dfaf6 <unknown>
E   #7 0x562b646c0db3 <unknown>
E   #8 0x562b6468fc10 <unknown>
E   #9 0x562b64690bee <unknown>
E   #10 0x562b64b013cb <unknown>
E   #11 0x562b64b05368 <unknown>
E   #12 0x562b64aeeeec <unknown>
E   #13 0x562b64b05ee7 <unknown>
E   #14 0x562b64ad413f <unknown>
E   #15 0x562b64b23858 <unknown>
E   #16 0x562b64b23a20 <unknown>
E   #17 0x562b64b33fb6 <unknown>
E   #18 0x7fc9f3955a94 <unknown>
E   #19 0x7fc9f39e2a34 __clone

During handling of the above exception, another exception occurred:
test_selenium_mc.py:104: in test_initiate_core_setup
    raise Exception("Failed to navigate to setup page - either the Go button was not clickable or the URL did not change as expected.")
E   Exception: Failed to navigate to setup page - either the Go button was not clickable or the URL did not change as expected.
___________________________ test_core_setup_save_btn ___________________________
test_selenium_mc.py:116: in test_core_setup_save_btn
    save_button = WebDriverWait(driver, 10).until(
../../.local/lib/python3.8/site-packages/selenium/webdriver/support/wait.py:105: in until
    raise TimeoutException(message, screen, stacktrace)
E   selenium.common.exceptions.TimeoutException: Message: 
E   Stacktrace:
E   #0 0x562b64b3513a <unknown>
E   #1 0x562b64650460 <unknown>
E   #2 0x562b6469cf96 <unknown>
E   #3 0x562b6469d221 <unknown>
E   #4 0x562b646e25d4 <unknown>
E   #5 0x562b646c103d <unknown>
E   #6 0x562b646dfaf6 <unknown>
E   #7 0x562b646c0db3 <unknown>
E   #8 0x562b6468fc10 <unknown>
E   #9 0x562b64690bee <unknown>
E   #10 0x562b64b013cb <unknown>
E   #11 0x562b64b05368 <unknown>
E   #12 0x562b64aeeeec <unknown>
E   #13 0x562b64b05ee7 <unknown>
E   #14 0x562b64ad413f <unknown>
E   #15 0x562b64b23858 <unknown>
E   #16 0x562b64b23a20 <unknown>
E   #17 0x562b64b33fb6 <unknown>
E   #18 0x7fc9f3955a94 <unknown>
E   #19 0x7fc9f39e2a34 __clone

During handling of the above exception, another exception occurred:
test_selenium_mc.py:128: in test_core_setup_save_btn
    raise Exception("Failed to find or click the core 'Save' button within the specified time.")
E   Exception: Failed to find or click the core 'Save' button within the specified time.
=========================== short test summary info ============================
FAILED test_selenium_mc.py::test_navigate_to_mc_console - selenium.common.exc...
FAILED test_selenium_mc.py::test_bootstrap_process_status - Exception: Failed...
FAILED test_selenium_mc.py::test_initiate_core_setup - Exception: Failed to n...
FAILED test_selenium_mc.py::test_core_setup_save_btn - Exception: Failed to f...
============================== 4 failed in 56.78s ==============================
