Repo Hash (Nightly Test):     [e2d2725]
Repo Hash (Cloudformation):   [d7ba267]
Nightly Test in the unity-cm account
Stack Name: [unity-cs-nightly-management-console]
Stack Status (Final): [CREATE_COMPLETE]
Stack Creation Time: [380 seconds] - PASS
============================= test session starts ==============================
platform linux -- Python 3.8.10, pytest-7.4.3, pluggy-1.3.0 -- /usr/bin/python3
cachedir: .pytest_cache
rootdir: /home/ubuntu/unity-cs-infra/nightly_tests/nightly_tests_ondemand
collecting ... collected 18 items

test_selenium_mc.py::test_navigate_to_url_with_cred PASSED               [  5%]
test_selenium_mc.py::test_acess_to_mc_console PASSED                     [ 11%]
test_selenium_mc.py::test_bootstrap_process FAILED                       [ 16%]
test_selenium_mc.py::test_initiate_core_setup FAILED                     [ 22%]
test_selenium_mc.py::test_input_venue_name FAILED                        [ 27%]
test_selenium_mc.py::test_input_project_name FAILED                      [ 33%]
test_selenium_mc.py::test_core_setup_save_btn FAILED                     [ 38%]
test_selenium_mc.py::test_return_to_marketplace FAILED                   [ 44%]
test_selenium_mc.py::test_grab_terminal_output FAILED                    [ 50%]
test_selenium_mc.py::test_install_eks FAILED                             [ 55%]
test_selenium_mc.py::test_eks_module_name FAILED                         [ 61%]
test_selenium_mc.py::test_eks_module_branch FAILED                       [ 66%]
test_selenium_mc.py::test_click_first_button FAILED                      [ 72%]
test_selenium_mc.py::test_click_second_button FAILED                     [ 77%]
test_selenium_mc.py::test_click_third_button FAILED                      [ 83%]
test_selenium_mc.py::test_click_fourth_button FAILED                     [ 88%]
test_selenium_mc.py::test_click_fith_button FAILED                       [ 94%]
test_selenium_mc.py::test_grab_terminal_output_two FAILED                [100%]

=================================== FAILURES ===================================
____________________________ test_bootstrap_process ____________________________
test_selenium_mc.py:86: in test_bootstrap_process
    assert "The Bootstrap Process Failed" not in status_message, "Bootstrap process failed"
E   AssertionError: Bootstrap process failed
E   assert 'The Bootstr...ocess Failed' not in 'The Bootstr...eck The Logs'
E     'The Bootstrap Process Failed' is contained here:
E       The Bootstrap Process Failed Please Check The Logs
___________________________ test_initiate_core_setup ___________________________
test_selenium_mc.py:101: in test_initiate_core_setup
    go_button = WebDriverWait(driver, 20).until(
../../../.local/lib/python3.8/site-packages/selenium/webdriver/support/wait.py:101: in until
    raise TimeoutException(message, screen, stacktrace)
E   selenium.common.exceptions.TimeoutException: Message: 
E   Stacktrace:
E   #0 0x56235d4e6f83 <unknown>
E   #1 0x56235d19fcf7 <unknown>
E   #2 0x56235d1ef99e <unknown>
E   #3 0x56235d1efaa1 <unknown>
E   #4 0x56235d23ad64 <unknown>
E   #5 0x56235d2190dd <unknown>
E   #6 0x56235d238006 <unknown>
E   #7 0x56235d218e53 <unknown>
E   #8 0x56235d1e0dd4 <unknown>
E   #9 0x56235d1e21de <unknown>
E   #10 0x56235d4ab531 <unknown>
E   #11 0x56235d4af455 <unknown>
E   #12 0x56235d497f55 <unknown>
E   #13 0x56235d4b00ef <unknown>
E   #14 0x56235d47b99f <unknown>
E   #15 0x56235d4d4008 <unknown>
E   #16 0x56235d4d41d7 <unknown>
E   #17 0x56235d4e6124 <unknown>
E   #18 0x7f05abccaac3 <unknown>

During handling of the above exception, another exception occurred:
test_selenium_mc.py:110: in test_initiate_core_setup
    raise Exception("Failed to navigate to setup page - either the Go button was not clickable or the URL did not change as expected.")
E   Exception: Failed to navigate to setup page - either the Go button was not clickable or the URL did not change as expected.
____________________________ test_input_venue_name _____________________________
test_selenium_mc.py:125: in test_input_venue_name
    text_box = WebDriverWait(driver, 10).until(
../../../.local/lib/python3.8/site-packages/selenium/webdriver/support/wait.py:101: in until
    raise TimeoutException(message, screen, stacktrace)
E   selenium.common.exceptions.TimeoutException: Message: 
E   Stacktrace:
E   #0 0x56235d4e6f83 <unknown>
E   #1 0x56235d19fcf7 <unknown>
E   #2 0x56235d1ef99e <unknown>
E   #3 0x56235d1efaa1 <unknown>
E   #4 0x56235d23ad64 <unknown>
E   #5 0x56235d2190dd <unknown>
E   #6 0x56235d238006 <unknown>
E   #7 0x56235d218e53 <unknown>
E   #8 0x56235d1e0dd4 <unknown>
E   #9 0x56235d1e21de <unknown>
E   #10 0x56235d4ab531 <unknown>
E   #11 0x56235d4af455 <unknown>
E   #12 0x56235d497f55 <unknown>
E   #13 0x56235d4b00ef <unknown>
E   #14 0x56235d47b99f <unknown>
E   #15 0x56235d4d4008 <unknown>
E   #16 0x56235d4d41d7 <unknown>
E   #17 0x56235d4e6124 <unknown>
E   #18 0x7f05abccaac3 <unknown>

During handling of the above exception, another exception occurred:
test_selenium_mc.py:132: in test_input_venue_name
    raise Exception(f"Failed to find or interact with the text box for venue name (ID: {element_id}).")
E   Exception: Failed to find or interact with the text box for venue name (ID: venue).
___________________________ test_input_project_name ____________________________
test_selenium_mc.py:147: in test_input_project_name
    text_box = WebDriverWait(driver, 10).until(
../../../.local/lib/python3.8/site-packages/selenium/webdriver/support/wait.py:101: in until
    raise TimeoutException(message, screen, stacktrace)
E   selenium.common.exceptions.TimeoutException: Message: 
E   Stacktrace:
E   #0 0x56235d4e6f83 <unknown>
E   #1 0x56235d19fcf7 <unknown>
E   #2 0x56235d1ef99e <unknown>
E   #3 0x56235d1efaa1 <unknown>
E   #4 0x56235d23ad64 <unknown>
E   #5 0x56235d2190dd <unknown>
E   #6 0x56235d238006 <unknown>
E   #7 0x56235d218e53 <unknown>
E   #8 0x56235d1e0dd4 <unknown>
E   #9 0x56235d1e21de <unknown>
E   #10 0x56235d4ab531 <unknown>
E   #11 0x56235d4af455 <unknown>
E   #12 0x56235d497f55 <unknown>
E   #13 0x56235d4b00ef <unknown>
E   #14 0x56235d47b99f <unknown>
E   #15 0x56235d4d4008 <unknown>
E   #16 0x56235d4d41d7 <unknown>
E   #17 0x56235d4e6124 <unknown>
E   #18 0x7f05abccaac3 <unknown>

During handling of the above exception, another exception occurred:
test_selenium_mc.py:154: in test_input_project_name
    raise Exception(f"Failed to find or interact with the text box for project name (ID: {element_id}).")
E   Exception: Failed to find or interact with the text box for project name (ID: project).
___________________________ test_core_setup_save_btn ___________________________
test_selenium_mc.py:167: in test_core_setup_save_btn
    save_button = WebDriverWait(driver, 10).until(
../../../.local/lib/python3.8/site-packages/selenium/webdriver/support/wait.py:101: in until
    raise TimeoutException(message, screen, stacktrace)
E   selenium.common.exceptions.TimeoutException: Message: 
E   Stacktrace:
E   #0 0x56235d4e6f83 <unknown>
E   #1 0x56235d19fcf7 <unknown>
E   #2 0x56235d1ef99e <unknown>
E   #3 0x56235d1efaa1 <unknown>
E   #4 0x56235d23ad64 <unknown>
E   #5 0x56235d2190dd <unknown>
E   #6 0x56235d238006 <unknown>
E   #7 0x56235d218e53 <unknown>
E   #8 0x56235d1e0dd4 <unknown>
E   #9 0x56235d1e21de <unknown>
E   #10 0x56235d4ab531 <unknown>
E   #11 0x56235d4af455 <unknown>
E   #12 0x56235d497f55 <unknown>
E   #13 0x56235d4b00ef <unknown>
E   #14 0x56235d47b99f <unknown>
E   #15 0x56235d4d4008 <unknown>
E   #16 0x56235d4d41d7 <unknown>
E   #17 0x56235d4e6124 <unknown>
E   #18 0x7f05abccaac3 <unknown>

During handling of the above exception, another exception occurred:
test_selenium_mc.py:173: in test_core_setup_save_btn
    raise Exception("Failed to find or click the core'Save' button within the specified time.")
E   Exception: Failed to find or click the core'Save' button within the specified time.
__________________________ test_return_to_marketplace __________________________
test_selenium_mc.py:194: in test_return_to_marketplace
    go_button = WebDriverWait(driver, 20).until(
../../../.local/lib/python3.8/site-packages/selenium/webdriver/support/wait.py:101: in until
    raise TimeoutException(message, screen, stacktrace)
E   selenium.common.exceptions.TimeoutException: Message: 
E   Stacktrace:
E   #0 0x56235d4e6f83 <unknown>
E   #1 0x56235d19fcf7 <unknown>
E   #2 0x56235d1ef99e <unknown>
E   #3 0x56235d1efaa1 <unknown>
E   #4 0x56235d23ad64 <unknown>
E   #5 0x56235d2190dd <unknown>
E   #6 0x56235d238006 <unknown>
E   #7 0x56235d218e53 <unknown>
E   #8 0x56235d1e0dd4 <unknown>
E   #9 0x56235d1e21de <unknown>
E   #10 0x56235d4ab531 <unknown>
E   #11 0x56235d4af455 <unknown>
E   #12 0x56235d497f55 <unknown>
E   #13 0x56235d4b00ef <unknown>
E   #14 0x56235d47b99f <unknown>
E   #15 0x56235d4d4008 <unknown>
E   #16 0x56235d4d41d7 <unknown>
E   #17 0x56235d4e6124 <unknown>
E   #18 0x7f05abccaac3 <unknown>

During handling of the above exception, another exception occurred:
test_selenium_mc.py:203: in test_return_to_marketplace
    raise Exception("Failed to navigate to the marketplace - either the button was not clickable or the URL did not change as expected.")
E   Exception: Failed to navigate to the marketplace - either the button was not clickable or the URL did not change as expected.
__________________________ test_grab_terminal_output ___________________________
test_selenium_mc.py:216: in test_grab_terminal_output
    terminal_output_element = WebDriverWait(driver, 10).until(
../../../.local/lib/python3.8/site-packages/selenium/webdriver/support/wait.py:101: in until
    raise TimeoutException(message, screen, stacktrace)
E   selenium.common.exceptions.TimeoutException: Message: 
E   Stacktrace:
E   #0 0x56235d4e6f83 <unknown>
E   #1 0x56235d19fcf7 <unknown>
E   #2 0x56235d1ef99e <unknown>
E   #3 0x56235d1efaa1 <unknown>
E   #4 0x56235d23ad64 <unknown>
E   #5 0x56235d2190dd <unknown>
E   #6 0x56235d238006 <unknown>
E   #7 0x56235d218e53 <unknown>
E   #8 0x56235d1e0dd4 <unknown>
E   #9 0x56235d1e21de <unknown>
E   #10 0x56235d4ab531 <unknown>
E   #11 0x56235d4af455 <unknown>
E   #12 0x56235d497f55 <unknown>
E   #13 0x56235d4b00ef <unknown>
E   #14 0x56235d47b99f <unknown>
E   #15 0x56235d4d4008 <unknown>
E   #16 0x56235d4d41d7 <unknown>
E   #17 0x56235d4e6124 <unknown>
E   #18 0x7f05abccaac3 <unknown>

During handling of the above exception, another exception occurred:
test_selenium_mc.py:221: in test_grab_terminal_output
    raise Exception("Failed to find or load the terminal output element within the specified time.")
E   Exception: Failed to find or load the terminal output element within the specified time.
_______________________________ test_install_eks _______________________________
test_selenium_mc.py:236: in test_install_eks
    install_button = WebDriverWait(driver, 10).until(
../../../.local/lib/python3.8/site-packages/selenium/webdriver/support/wait.py:101: in until
    raise TimeoutException(message, screen, stacktrace)
E   selenium.common.exceptions.TimeoutException: Message: 
E   Stacktrace:
E   #0 0x56235d4e6f83 <unknown>
E   #1 0x56235d19fcf7 <unknown>
E   #2 0x56235d1ef99e <unknown>
E   #3 0x56235d1efaa1 <unknown>
E   #4 0x56235d23ad64 <unknown>
E   #5 0x56235d2190dd <unknown>
E   #6 0x56235d238006 <unknown>
E   #7 0x56235d218e53 <unknown>
E   #8 0x56235d1e0dd4 <unknown>
E   #9 0x56235d1e21de <unknown>
E   #10 0x56235d4ab531 <unknown>
E   #11 0x56235d4af455 <unknown>
E   #12 0x56235d497f55 <unknown>
E   #13 0x56235d4b00ef <unknown>
E   #14 0x56235d47b99f <unknown>
E   #15 0x56235d4d4008 <unknown>
E   #16 0x56235d4d41d7 <unknown>
E   #17 0x56235d4e6124 <unknown>
E   #18 0x7f05abccaac3 <unknown>

During handling of the above exception, another exception occurred:
test_selenium_mc.py:245: in test_install_eks
    raise Exception("Failed to install EKS - either the button was not clickable or the URL did not update as expected.")
E   Exception: Failed to install EKS - either the button was not clickable or the URL did not update as expected.
_____________________________ test_eks_module_name _____________________________
test_selenium_mc.py:257: in test_eks_module_name
    text_box = WebDriverWait(driver, 10).until(
../../../.local/lib/python3.8/site-packages/selenium/webdriver/support/wait.py:101: in until
    raise TimeoutException(message, screen, stacktrace)
E   selenium.common.exceptions.TimeoutException: Message: 
E   Stacktrace:
E   #0 0x56235d4e6f83 <unknown>
E   #1 0x56235d19fcf7 <unknown>
E   #2 0x56235d1ef99e <unknown>
E   #3 0x56235d1efaa1 <unknown>
E   #4 0x56235d23ad64 <unknown>
E   #5 0x56235d2190dd <unknown>
E   #6 0x56235d238006 <unknown>
E   #7 0x56235d218e53 <unknown>
E   #8 0x56235d1e0dd4 <unknown>
E   #9 0x56235d1e21de <unknown>
E   #10 0x56235d4ab531 <unknown>
E   #11 0x56235d4af455 <unknown>
E   #12 0x56235d497f55 <unknown>
E   #13 0x56235d4b00ef <unknown>
E   #14 0x56235d47b99f <unknown>
E   #15 0x56235d4d4008 <unknown>
E   #16 0x56235d4d41d7 <unknown>
E   #17 0x56235d4e6124 <unknown>
E   #18 0x7f05abccaac3 <unknown>

During handling of the above exception, another exception occurred:
test_selenium_mc.py:261: in test_eks_module_name
    raise Exception(f"Textbox for module name (ID: {element_id}) not found.")
E   Exception: Textbox for module name (ID: module) not found.
____________________________ test_eks_module_branch ____________________________
test_selenium_mc.py:275: in test_eks_module_branch
    text_box = WebDriverWait(driver, 10).until(
../../../.local/lib/python3.8/site-packages/selenium/webdriver/support/wait.py:101: in until
    raise TimeoutException(message, screen, stacktrace)
E   selenium.common.exceptions.TimeoutException: Message: 
E   Stacktrace:
E   #0 0x56235d4e6f83 <unknown>
E   #1 0x56235d19fcf7 <unknown>
E   #2 0x56235d1ef99e <unknown>
E   #3 0x56235d1efaa1 <unknown>
E   #4 0x56235d23ad64 <unknown>
E   #5 0x56235d2190dd <unknown>
E   #6 0x56235d238006 <unknown>
E   #7 0x56235d218e53 <unknown>
E   #8 0x56235d1e0dd4 <unknown>
E   #9 0x56235d1e21de <unknown>
E   #10 0x56235d4ab531 <unknown>
E   #11 0x56235d4af455 <unknown>
E   #12 0x56235d497f55 <unknown>
E   #13 0x56235d4b00ef <unknown>
E   #14 0x56235d47b99f <unknown>
E   #15 0x56235d4d4008 <unknown>
E   #16 0x56235d4d41d7 <unknown>
E   #17 0x56235d4e6124 <unknown>
E   #18 0x7f05abccaac3 <unknown>

During handling of the above exception, another exception occurred:
test_selenium_mc.py:279: in test_eks_module_branch
    raise Exception(f"Textbox for branch name (ID: {element_id}) not found.")
E   Exception: Textbox for branch name (ID: branch) not found.
___________________________ test_click_first_button ____________________________
test_selenium_mc.py:292: in test_click_first_button
    button = WebDriverWait(driver, 10).until(
../../../.local/lib/python3.8/site-packages/selenium/webdriver/support/wait.py:101: in until
    raise TimeoutException(message, screen, stacktrace)
E   selenium.common.exceptions.TimeoutException: Message: 
E   Stacktrace:
E   #0 0x56235d4e6f83 <unknown>
E   #1 0x56235d19fcf7 <unknown>
E   #2 0x56235d1ef99e <unknown>
E   #3 0x56235d1efaa1 <unknown>
E   #4 0x56235d23ad64 <unknown>
E   #5 0x56235d2190dd <unknown>
E   #6 0x56235d238006 <unknown>
E   #7 0x56235d218e53 <unknown>
E   #8 0x56235d1e0dd4 <unknown>
E   #9 0x56235d1e21de <unknown>
E   #10 0x56235d4ab531 <unknown>
E   #11 0x56235d4af455 <unknown>
E   #12 0x56235d497f55 <unknown>
E   #13 0x56235d4b00ef <unknown>
E   #14 0x56235d47b99f <unknown>
E   #15 0x56235d4d4008 <unknown>
E   #16 0x56235d4d41d7 <unknown>
E   #17 0x56235d4e6124 <unknown>
E   #18 0x7f05abccaac3 <unknown>

During handling of the above exception, another exception occurred:
test_selenium_mc.py:297: in test_click_first_button
    raise Exception(f"Failed to find or click the first button (class: {button_class}).")
E   Exception: Failed to find or click the first button (class: default-btn.next-step.svelte-1pvzwgg).
___________________________ test_click_second_button ___________________________
test_selenium_mc.py:308: in test_click_second_button
    button = WebDriverWait(driver, 10).until(
../../../.local/lib/python3.8/site-packages/selenium/webdriver/support/wait.py:101: in until
    raise TimeoutException(message, screen, stacktrace)
E   selenium.common.exceptions.TimeoutException: Message: 
E   Stacktrace:
E   #0 0x56235d4e6f83 <unknown>
E   #1 0x56235d19fcf7 <unknown>
E   #2 0x56235d1ef99e <unknown>
E   #3 0x56235d1efaa1 <unknown>
E   #4 0x56235d23ad64 <unknown>
E   #5 0x56235d2190dd <unknown>
E   #6 0x56235d238006 <unknown>
E   #7 0x56235d218e53 <unknown>
E   #8 0x56235d1e0dd4 <unknown>
E   #9 0x56235d1e21de <unknown>
E   #10 0x56235d4ab531 <unknown>
E   #11 0x56235d4af455 <unknown>
E   #12 0x56235d497f55 <unknown>
E   #13 0x56235d4b00ef <unknown>
E   #14 0x56235d47b99f <unknown>
E   #15 0x56235d4d4008 <unknown>
E   #16 0x56235d4d41d7 <unknown>
E   #17 0x56235d4e6124 <unknown>
E   #18 0x7f05abccaac3 <unknown>

During handling of the above exception, another exception occurred:
test_selenium_mc.py:313: in test_click_second_button
    raise Exception(f"Failed to find or click the second button (class: {button_class}).")
E   Exception: Failed to find or click the second button (class: default-btn.next-step.svelte-1pvzwgg).
___________________________ test_click_third_button ____________________________
test_selenium_mc.py:324: in test_click_third_button
    button = WebDriverWait(driver, 10).until(
../../../.local/lib/python3.8/site-packages/selenium/webdriver/support/wait.py:101: in until
    raise TimeoutException(message, screen, stacktrace)
E   selenium.common.exceptions.TimeoutException: Message: 
E   Stacktrace:
E   #0 0x56235d4e6f83 <unknown>
E   #1 0x56235d19fcf7 <unknown>
E   #2 0x56235d1ef99e <unknown>
E   #3 0x56235d1efaa1 <unknown>
E   #4 0x56235d23ad64 <unknown>
E   #5 0x56235d2190dd <unknown>
E   #6 0x56235d238006 <unknown>
E   #7 0x56235d218e53 <unknown>
E   #8 0x56235d1e0dd4 <unknown>
E   #9 0x56235d1e21de <unknown>
E   #10 0x56235d4ab531 <unknown>
E   #11 0x56235d4af455 <unknown>
E   #12 0x56235d497f55 <unknown>
E   #13 0x56235d4b00ef <unknown>
E   #14 0x56235d47b99f <unknown>
E   #15 0x56235d4d4008 <unknown>
E   #16 0x56235d4d41d7 <unknown>
E   #17 0x56235d4e6124 <unknown>
E   #18 0x7f05abccaac3 <unknown>

During handling of the above exception, another exception occurred:
test_selenium_mc.py:329: in test_click_third_button
    raise Exception(f"Failed to find or click the third button (class: {button_class}).")
E   Exception: Failed to find or click the third button (class: default-btn.next-step.svelte-1pvzwgg).
___________________________ test_click_fourth_button ___________________________
test_selenium_mc.py:373: in test_click_fourth_button
    button = WebDriverWait(driver, 10).until(
../../../.local/lib/python3.8/site-packages/selenium/webdriver/support/wait.py:101: in until
    raise TimeoutException(message, screen, stacktrace)
E   selenium.common.exceptions.TimeoutException: Message: 
E   Stacktrace:
E   #0 0x56235d4e6f83 <unknown>
E   #1 0x56235d19fcf7 <unknown>
E   #2 0x56235d1ef99e <unknown>
E   #3 0x56235d1efaa1 <unknown>
E   #4 0x56235d23ad64 <unknown>
E   #5 0x56235d2190dd <unknown>
E   #6 0x56235d238006 <unknown>
E   #7 0x56235d218e53 <unknown>
E   #8 0x56235d1e0dd4 <unknown>
E   #9 0x56235d1e21de <unknown>
E   #10 0x56235d4ab531 <unknown>
E   #11 0x56235d4af455 <unknown>
E   #12 0x56235d497f55 <unknown>
E   #13 0x56235d4b00ef <unknown>
E   #14 0x56235d47b99f <unknown>
E   #15 0x56235d4d4008 <unknown>
E   #16 0x56235d4d41d7 <unknown>
E   #17 0x56235d4e6124 <unknown>
E   #18 0x7f05abccaac3 <unknown>

During handling of the above exception, another exception occurred:
test_selenium_mc.py:378: in test_click_fourth_button
    raise Exception(f"Failed to find or click the fourth button (class: {button_class}).")
E   Exception: Failed to find or click the fourth button (class: btn.btn-primary.svelte-1pvzwgg).
____________________________ test_click_fith_button ____________________________
test_selenium_mc.py:356: in test_click_fith_button
    button = WebDriverWait(driver, 10).until(
../../../.local/lib/python3.8/site-packages/selenium/webdriver/support/wait.py:101: in until
    raise TimeoutException(message, screen, stacktrace)
E   selenium.common.exceptions.TimeoutException: Message: 
E   Stacktrace:
E   #0 0x56235d4e6f83 <unknown>
E   #1 0x56235d19fcf7 <unknown>
E   #2 0x56235d1ef99e <unknown>
E   #3 0x56235d1efaa1 <unknown>
E   #4 0x56235d23ad64 <unknown>
E   #5 0x56235d2190dd <unknown>
E   #6 0x56235d238006 <unknown>
E   #7 0x56235d218e53 <unknown>
E   #8 0x56235d1e0dd4 <unknown>
E   #9 0x56235d1e21de <unknown>
E   #10 0x56235d4ab531 <unknown>
E   #11 0x56235d4af455 <unknown>
E   #12 0x56235d497f55 <unknown>
E   #13 0x56235d4b00ef <unknown>
E   #14 0x56235d47b99f <unknown>
E   #15 0x56235d4d4008 <unknown>
E   #16 0x56235d4d41d7 <unknown>
E   #17 0x56235d4e6124 <unknown>
E   #18 0x7f05abccaac3 <unknown>

During handling of the above exception, another exception occurred:
test_selenium_mc.py:361: in test_click_fith_button
    raise Exception(f"Failed to find or click the fourth button (class: {button_class}).")
E   Exception: Failed to find or click the fourth button (class: btn.btn-primary.svelte-1pvzwgg).
________________________ test_grab_terminal_output_two _________________________
test_selenium_mc.py:391: in test_grab_terminal_output_two
    terminal_output_element = WebDriverWait(driver, 10).until(
../../../.local/lib/python3.8/site-packages/selenium/webdriver/support/wait.py:101: in until
    raise TimeoutException(message, screen, stacktrace)
E   selenium.common.exceptions.TimeoutException: Message: 
E   Stacktrace:
E   #0 0x56235d4e6f83 <unknown>
E   #1 0x56235d19fcf7 <unknown>
E   #2 0x56235d1ef99e <unknown>
E   #3 0x56235d1efaa1 <unknown>
E   #4 0x56235d23ad64 <unknown>
E   #5 0x56235d2190dd <unknown>
E   #6 0x56235d238006 <unknown>
E   #7 0x56235d218e53 <unknown>
E   #8 0x56235d1e0dd4 <unknown>
E   #9 0x56235d1e21de <unknown>
E   #10 0x56235d4ab531 <unknown>
E   #11 0x56235d4af455 <unknown>
E   #12 0x56235d497f55 <unknown>
E   #13 0x56235d4b00ef <unknown>
E   #14 0x56235d47b99f <unknown>
E   #15 0x56235d4d4008 <unknown>
E   #16 0x56235d4d41d7 <unknown>
E   #17 0x56235d4e6124 <unknown>
E   #18 0x7f05abccaac3 <unknown>

During handling of the above exception, another exception occurred:
test_selenium_mc.py:395: in test_grab_terminal_output_two
    raise Exception("Failed to find or load the terminal output element within the specified time.")
E   Exception: Failed to find or load the terminal output element within the specified time.
=========================== short test summary info ============================
FAILED test_selenium_mc.py::test_bootstrap_process - AssertionError: Bootstra...
FAILED test_selenium_mc.py::test_initiate_core_setup - Exception: Failed to n...
FAILED test_selenium_mc.py::test_input_venue_name - Exception: Failed to find...
FAILED test_selenium_mc.py::test_input_project_name - Exception: Failed to fi...
FAILED test_selenium_mc.py::test_core_setup_save_btn - Exception: Failed to f...
FAILED test_selenium_mc.py::test_return_to_marketplace - Exception: Failed to...
FAILED test_selenium_mc.py::test_grab_terminal_output - Exception: Failed to ...
FAILED test_selenium_mc.py::test_install_eks - Exception: Failed to install E...
FAILED test_selenium_mc.py::test_eks_module_name - Exception: Textbox for mod...
FAILED test_selenium_mc.py::test_eks_module_branch - Exception: Textbox for b...
FAILED test_selenium_mc.py::test_click_first_button - Exception: Failed to fi...
FAILED test_selenium_mc.py::test_click_second_button - Exception: Failed to f...
FAILED test_selenium_mc.py::test_click_third_button - Exception: Failed to fi...
FAILED test_selenium_mc.py::test_click_fourth_button - Exception: Failed to f...
FAILED test_selenium_mc.py::test_click_fith_button - Exception: Failed to fin...
FAILED test_selenium_mc.py::test_grab_terminal_output_two - Exception: Failed...
=================== 16 failed, 2 passed in 200.63s (0:03:20) ===================
