Repo Hash (Nightly Test):     [6be7f57]
Deploying Cloudformation stack...
-----------------------------------------
Items that will auto-deploy on bootstrap:
Marketplace Item                | Version
--------------------------------+--------
unity-cs-monitoring-lambda      | 0.1
unity-apigateway                | 0.4
unity-proxy                     | 0.14
unity-ui                        | 0.8.0
Nightly Test in the (TODO FIXME) account
Stack Name: [unity-management-console-unity-nightly]
Stack Status (Final): [CREATE_COMPLETE]
Stack Creation Time: [420 seconds] - PASS
Deploying Management Console...
============================= test session starts ==============================
platform linux -- Python 3.8.10, pytest-8.3.2, pluggy-1.5.0 -- /usr/bin/python3
cachedir: .pytest_cache
rootdir: /home/ubuntu/unity-cs-infra/nightly_tests
collecting ... collected 4 items

test_selenium_mc.py::test_navigate_to_mc_console FAILED                  [ 25%]
test_selenium_mc.py::test_bootstrap_process_status FAILED                [ 50%]
test_selenium_mc.py::test_initiate_core_setup FAILED                     [ 75%]
test_selenium_mc.py::test_core_setup_save_btn FAILED                     [100%]

=================================== FAILURES ===================================
_________________________ test_navigate_to_mc_console __________________________
test_selenium_mc.py:59: in test_navigate_to_mc_console
    assert driver.current_url.lower() == expected_url.lower(), f"URL does not match the expected URL without credentials. Expected: {expected_url}, but got: {driver.current_url}"
E   AssertionError: URL does not match the expected URL without credentials. Expected: HTTP://unity-nightly-httpd-alb-1493133584.us-west-2.elb.amazonaws.com:8080/unity/nightly/management/ui/landing, but got: http://unity-nightly-httpd-alb-1493133584.us-west-2.elb.amazonaws.com:8080/unity/nightly/management/ui
E   assert 'http://unity...management/ui' == 'http://unity...nt/ui/landing'
E     
E     - http://unity-nightly-httpd-alb-1493133584.us-west-2.elb.amazonaws.com:8080/unity/nightly/management/ui/landing
E     ?                                                                                                       --------
E     + http://unity-nightly-httpd-alb-1493133584.us-west-2.elb.amazonaws.com:8080/unity/nightly/management/ui
________________________ test_bootstrap_process_status _________________________
test_selenium_mc.py:77: in test_bootstrap_process_status
    bootstrap_status_element = WebDriverWait(driver, 10).until(
../../.local/lib/python3.8/site-packages/selenium/webdriver/support/wait.py:105: in until
    raise TimeoutException(message, screen, stacktrace)
E   selenium.common.exceptions.TimeoutException: Message: 
E   Stacktrace:
E   #0 0x558e22d9313a <unknown>
E   #1 0x558e228ae460 <unknown>
E   #2 0x558e228faf96 <unknown>
E   #3 0x558e228fb221 <unknown>
E   #4 0x558e229405d4 <unknown>
E   #5 0x558e2291f03d <unknown>
E   #6 0x558e2293daf6 <unknown>
E   #7 0x558e2291edb3 <unknown>
E   #8 0x558e228edc10 <unknown>
E   #9 0x558e228eebee <unknown>
E   #10 0x558e22d5f3cb <unknown>
E   #11 0x558e22d63368 <unknown>
E   #12 0x558e22d4ceec <unknown>
E   #13 0x558e22d63ee7 <unknown>
E   #14 0x558e22d3213f <unknown>
E   #15 0x558e22d81858 <unknown>
E   #16 0x558e22d81a20 <unknown>
E   #17 0x558e22d91fb6 <unknown>
E   #18 0x7f636ae05a94 <unknown>
E   #19 0x7f636ae92a34 __clone

During handling of the above exception, another exception occurred:
test_selenium_mc.py:89: in test_bootstrap_process_status
    raise Exception("Failed to find the bootstrap status message within the specified time.")
E   Exception: Failed to find the bootstrap status message within the specified time.
___________________________ test_initiate_core_setup ___________________________
test_selenium_mc.py:95: in test_initiate_core_setup
    go_button = WebDriverWait(driver, 20).until(
../../.local/lib/python3.8/site-packages/selenium/webdriver/support/wait.py:105: in until
    raise TimeoutException(message, screen, stacktrace)
E   selenium.common.exceptions.TimeoutException: Message: 
E   Stacktrace:
E   #0 0x558e22d9313a <unknown>
E   #1 0x558e228ae460 <unknown>
E   #2 0x558e228faf96 <unknown>
E   #3 0x558e228fb221 <unknown>
E   #4 0x558e229405d4 <unknown>
E   #5 0x558e2291f03d <unknown>
E   #6 0x558e2293daf6 <unknown>
E   #7 0x558e2291edb3 <unknown>
E   #8 0x558e228edc10 <unknown>
E   #9 0x558e228eebee <unknown>
E   #10 0x558e22d5f3cb <unknown>
E   #11 0x558e22d63368 <unknown>
E   #12 0x558e22d4ceec <unknown>
E   #13 0x558e22d63ee7 <unknown>
E   #14 0x558e22d3213f <unknown>
E   #15 0x558e22d81858 <unknown>
E   #16 0x558e22d81a20 <unknown>
E   #17 0x558e22d91fb6 <unknown>
E   #18 0x7f636ae05a94 <unknown>
E   #19 0x7f636ae92a34 __clone

During handling of the above exception, another exception occurred:
test_selenium_mc.py:104: in test_initiate_core_setup
    raise Exception("Failed to navigate to setup page - either the Go button was not clickable or the URL did not change as expected.")
E   Exception: Failed to navigate to setup page - either the Go button was not clickable or the URL did not change as expected.
___________________________ test_core_setup_save_btn ___________________________
test_selenium_mc.py:116: in test_core_setup_save_btn
    save_button = WebDriverWait(driver, 10).until(
../../.local/lib/python3.8/site-packages/selenium/webdriver/support/wait.py:105: in until
    raise TimeoutException(message, screen, stacktrace)
E   selenium.common.exceptions.TimeoutException: Message: 
E   Stacktrace:
E   #0 0x558e22d9313a <unknown>
E   #1 0x558e228ae460 <unknown>
E   #2 0x558e228faf96 <unknown>
E   #3 0x558e228fb221 <unknown>
E   #4 0x558e229405d4 <unknown>
E   #5 0x558e2291f03d <unknown>
E   #6 0x558e2293daf6 <unknown>
E   #7 0x558e2291edb3 <unknown>
E   #8 0x558e228edc10 <unknown>
E   #9 0x558e228eebee <unknown>
E   #10 0x558e22d5f3cb <unknown>
E   #11 0x558e22d63368 <unknown>
E   #12 0x558e22d4ceec <unknown>
E   #13 0x558e22d63ee7 <unknown>
E   #14 0x558e22d3213f <unknown>
E   #15 0x558e22d81858 <unknown>
E   #16 0x558e22d81a20 <unknown>
E   #17 0x558e22d91fb6 <unknown>
E   #18 0x7f636ae05a94 <unknown>
E   #19 0x7f636ae92a34 __clone

During handling of the above exception, another exception occurred:
test_selenium_mc.py:128: in test_core_setup_save_btn
    raise Exception("Failed to find or click the core 'Save' button within the specified time.")
E   Exception: Failed to find or click the core 'Save' button within the specified time.
=========================== short test summary info ============================
FAILED test_selenium_mc.py::test_navigate_to_mc_console - AssertionError: URL...
FAILED test_selenium_mc.py::test_bootstrap_process_status - Exception: Failed...
FAILED test_selenium_mc.py::test_initiate_core_setup - Exception: Failed to n...
FAILED test_selenium_mc.py::test_core_setup_save_btn - Exception: Failed to f...
======================== 4 failed in 119.38s (0:01:59) =========================
